Workbook
Name team_conf: #REF!
Name picks: #REF!
Name vac_opp: #REF!

Sheet 2020
A1: Player | B1: School | C1: Pick_Num | D1: Team | E1: GP | F1: Rec | G1: Rec_Yds | H1: Rec_Yds_Game | I1: YPC | J1: Rec_TDs | K1: Rush_Att | L1: Rush_Yds | M1: Rush_YPA | N1: Rush_TDs | O1: Fumbles | P1: Col_FPPG | Q1: Rec_Percentage | R1: TD_Percentage | S1: Dominator | T1: Vac_Tar | U1: Age | V1: Height
A2: Henry Ruggs | B2: Alabama | C2: 12 | D2: LV | E2: 12 | F2: 40 | G2: 746 | H2: =G2/E2 -> 62.166667 | I2: 18.65 | J2: 7 | K2: 2 | L2: 75 | M2: 37.5 | N2: 1 | O2: 0 | P2: =(F2*0.5+G2/10+J2*6+L2/10+N2*6-O2*2)/E2 -> 12.508333 | Q2: =40/287*100 -> 13.937282 | R2: =7/49*100 -> 14.285714 | S2: =(746+7)/(4449+49)*100 -> 16.740774 | T2: 47.41 | U2: 21.260274 | V2: =6*12 -> 72
A3: Jerry Jeudy | B3: Alabama | C3: 15 | D3: DEN | E3: 13 | F3: 77 | G3: 1163 | H3: =G3/E3 -> 89.461538 | I3: 15.1 | J3: 10 | K3: 1 | L3: 1 | M3: 1 | N3: 0 | O3: 0 | P3: =(F3*0.5+G3/10+J3*6+L3/10+N3*6-O3*2)/E3 -> 16.530769 | Q3: =77/287*100 -> 26.829268 | R3: =10/49*100 -> 20.408163 | S3: =(1163+10)/(4449+49)*100 -> 26.078257 | T3: =44/262*100 -> 16.793893 | U3: 21.016438 | V3: =6*12+1 -> 73
A4: CeeDee Lamb | B4: Oklahoma | C4: 17 | D4: DAL | E4: 13 | F4: 62 | G4: 1327 | H4: =G4/E4 -> 102.07692 | I4: 21.4 | J4: 14 | K4: 9 | L4: 20 | M4: 2.22 | N4: 1 | O4: 2 | P4: =(F4*0.5+G4/10+J4*6+L4/10+N4*6-O4*2)/E4 -> 19.361538 | Q4: =62/262*100 -> 23.664122 | R4: =14/36*100 -> 38.888889 | S4: =(1327+14)/(4164+36)*100 -> 31.928571 | T4: 32.77 | U4: 21.063014 | V4: =6*12+2 -> 74
A5: Jalen Reagor | B5: TCU | C5: 21 | D5: PHI | E5: 12 | F5: 43 | G5: 611 | H5: =G5/E5 -> 50.916667 | I5: 14.21 | J5: 5 | K5: 14 | L5: 89 | M5: 6.36 | N5: 0 | O5: 6 | P5: =(F5*0.5+G5/10+J5*6+L5/10+N5*6-O5*2)/E5 -> 9.125 | Q5: =43/211*100 -> 20.379147 | R5: =5/15*100 -> 33.333333 | S5: =(5+611)/(2444+15)*100 -> 25.050834 | T5: 42.23 | U5: 21.331507 | V5: =5*12+11 -> 71
A6: Justin Jefferson | B6: LSU | C6: 22 | D6: MIN | E6: 15 | F6: 111 | G6: 1540 | H6: =G6/E6 -> 102.66667 | I6: 13.87 | J6: 18 | K6: 0 | L6: 0 | M6: 0 | N6: 0 | O6: 0 | P6: =(F6*0.5+G6/10+J6*6+L6/10+N6*6-O6*2)/E6 -> 21.166667 | Q6: =111/426*100 -> 26.056338 | R6: =18/61*100 -> 29.508197 | S6: =(18+1540)/(6024+61)*100 -> 25.603944 | T6: 52.63 | U6: 21.293151 | V6: =6*12+1 -> 73
A7: Brandon Aiyuk | B7: Arizona State | C7: 25 | D7: SF | E7: 12 | F7: 65 | G7: 1192 | H7: =G7/E7 -> 99.333333 | I7: 18.34 | J7: 8 | K7: 1 | L7: 6 | M7: 6 | N7: 0 | O7: 1 | P7: =(F7*0.5+G7/10+J7*6+L7/10+N7*6-O7*2)/E7 -> 16.525 | Q7: =65/233*100 -> 27.896996 | R7: =8/21*100 -> 38.095238 | S7: =(8+1192)/(3235+21)*100 -> 36.855037 | T7: 48.927 | U7: 22.131507 | V7: =6*12 -> 72
A8: Tee Higgins | B8: Clemson | C8: 33 | D8: CIN | E8: 15 | F8: 59 | G8: 1167 | H8: =G8/E8 -> 77.8 | I8: 19.78 | J8: 13 | K8: 1 | L8: 36 | M8: 36 | N8: 1 | O8: 0 | P8: =(F8*0.5+G8/10+J8*6+L8/10+N8*6-O8*2)/E8 -> 15.586667 | Q8: =59/326*100 -> 18.09816 | R8: =13/40*100 -> 32.5 | S8: =(13+1167)/(4325+40)*100 -> 27.033219 | T8: =16/388*100 -> 4.1237113 | U8: 21.293151 | V8: =6*12+4 -> 76
A9: Michael Pittman Jr. | B9: USC | C9: 34 | D9: IND | E9: 13 | F9: 101 | G9: 1275 | H9: =G9/E9 -> 98.076923 | I9: 12.62 | J9: 11 | K9: 0 | L9: 0 | M9: 0 | N9: 0 | O9: 1 | P9: =(F9*0.5+G9/10+J9*6+L9/10+N9*6-O9*2)/E9 -> 18.615385 | Q9: =101/365*100 -> 27.671233 | R9: =11/35*100 -> 31.428571 | S9: =(11+1275)/(4365+35)*100 -> 29.227273 | T9: 21.96 | U9: 22.583562 | V9: =6*12+4 -> 76
A10: Laviska Shenault | B10: Colorado | C10: 42 | D10: JAX | E10: 11 | F10: 56 | G10: 764 | H10: =G10/E10 -> 69.454545 | I10: 13.64 | J10: 4 | K10: 23 | L10: 161 | M10: 7 | N10: 2 | O10: 1 | P10: =(F10*0.5+G10/10+J10*6+L10/10+N10*6-O10*2)/E10 -> 14.045455 | Q10: =56/257*100 -> 21.789883 | R10: =4/18*100 -> 22.222222 | S10: =(4+764)/(2858+18)*100 -> 26.703755 | T10: 3.098 | U10: 21.586301 | V10: =6*12+1 -> 73
A11: K.J. Hamler | B11: Penn State | C11: 46 | D11: DEN | E11: 13 | F11: 56 | G11: 904 | H11: =G11/E11 -> 69.538462 | I11: 16.14 | J11: 8 | K11: 13 | L11: 43 | M11: 3.31 | N11: 0 | O11: 3 | P11: =(F11*0.5+G11/10+J11*6+L11/10+N11*6-O11*2)/E11 -> 12.669231 | Q11: =56/217*100 -> 25.806452 | R11: =8/25*100 -> 32 | S11: =(8+904)/(2887+25)*100 -> 31.318681 | T11: =44/262*100 -> 16.793893 | U11: 20.832877 | V11: =5*12+9 -> 69
A12: Chase Claypool | B12: Notre Dame | C12: 49 | D12: PIT | E12: 13 | F12: 66 | G12: 1037 | H12: =G12/E12 -> 79.769231 | I12: 15.71 | J12: 13 | K12: 0 | L12: 0 | M12: 0 | N12: 0 | O12: 0 | P12: =(F12*0.5+G12/10+J12*6+L12/10+N12*6-O12*2)/E12 -> 16.515385 | Q12: =66/253*100 -> 26.086957 | R12: =13/37*100 -> 35.135135 | S12: =(13+1037)/(3278+37)*100 -> 31.674208 | T12: 17.056 | U12: 21.838356 | V12: =6*12+4 -> 76
A13: Van Jefferson | B13: Florida | C13: 57 | D13: LAR | E13: 13 | F13: 49 | G13: 657 | H13: =G13/E13 -> 50.538462 | I13: 13.41 | J13: 6 | K13: 1 | L13: 7 | M13: 7 | N13: 0 | O13: 0 | P13: =(F13*0.5+G13/10+J13*6+L13/10+N13*6-O13*2)/E13 -> 9.7615385 | Q13: =49/317*100 -> 15.457413 | R13: =6/33*100 -> 18.181818 | S13: =(6+657)/(3910+33)*100 -> 16.814608 | T13: 19.592 | U13: 23.789041 | V13: =6*12+1 -> 73
A14: Denzel Mims | B14: Baylor | C14: 59 | D14: NYJ | E14: 14 | F14: 66 | G14: 1020 | H14: =G14/E14 -> 72.857143 | I14: 15.45 | J14: 12 | K14: 0 | L14: 0 | M14: 0 | N14: 0 | O14: 2 | P14: =(F14*0.5+G14/10+J14*6+L14/10+N14*6-O14*2)/E14 -> 14.5 | Q14: =66/277*100 -> 23.826715 | R14: =12/24*100 -> 50 | S14: =(12+1020)/(3571+24)*100 -> 28.706537 | T14: 51.3 | U14: 22.583562 | V14: =6*12+3 -> 75
A15: Bryan Edwards | B15: South Carolina | C15: 81 | D15: LV | E15: 10 | F15: 71 | G15: 816 | H15: =G15/E15 -> 81.6 | I15: 11.49 | J15: 6 | K15: 2 | L15: 22 | M15: 11 | N15: 0 | O15: 0 | P15: =(F15*0.5+G15/10+J15*6+L15/10+N15*6-O15*2)/E15 -> 15.53 | Q15: =71/268*100 -> 26.492537 | R15: =6/12*100 -> 50 | S15: =(6+816)/(2667+12)*100 -> 30.683091 | T15: 47.41 | U15: 21.493151 | V15: =6*12+3 -> 75
A16: Devin Duvernay | B16: Texas | C16: 92 | D16: BAL | E16: 13 | F16: 106 | G16: 1386 | H16: =G16/E16 -> 106.61538 | I16: 13.08 | J16: 9 | K16: 10 | L16: 24 | M16: 2.4 | N16: 1 | O16: 0 | P16: =(F16*0.5+G16/10+J16*6+L16/10+N16*6-O16*2)/E16 -> 19.538462 | Q16: =106/306*100 -> 34.640523 | R16: =9/32*100 -> 28.125 | S16: =(1386+9)/(3761+32)*100 -> 36.778276 | T16: 20.879 | U16: 22.665753 | V16: =5*12+11 -> 71
A17: Gabriel Davis | B17: UCF | C17: 128 | D17: BUF | E17: 12 | F17: 72 | G17: 1241 | H17: =G17/E17 -> 103.41667 | I17: 17.24 | J17: 12 | K17: 0 | L17: 0 | M17: 0 | N17: 0 | O17: 0 | P17: =(F17*0.5+G17/10+J17*6+L17/10+N17*6-O17*2)/E17 -> 19.341667 | Q17: =72/271*100 -> 26.568266 | R17: =12/36*100 -> 33.333333 | S17: =(1241+12)/(4117+36)*100 -> 30.170961 | T17: 11.18 | U17: 21.117808 | V17: =6*12+2 -> 74
A18: Antonio Gandy-Golden | B18: Liberty | C18: 142 | D18: WAS | E18: 13 | F18: 79 | G18: 1396 | H18: =G18/E18 -> 107.38462 | I18: 17.67 | J18: 10 | K18: 0 | L18: 0 | M18: 0 | N18: 0 | O18: NA | P18: =(F18*0.5+G18/10+J18*6+L18/10+N18*6-O18*2)/E18 -> #VALUE! | Q18: =79/257*100 -> 30.7393 | R18: =10/29*100 -> 34.482759 | S18: =(10+1396)/(29+3756)*100 -> 37.146631 | T18: 47.038 | U18: 22.093151 | V18: =6*12+4 -> 76
A19: Joe Reed | B19: Virginia | C19: 151 | D19: LAC | E19: 13 | F19: 77 | G19: 679 | H19: =G19/E19 -> 52.230769 | I19: 8.82 | J19: 7 | K19: 8 | L19: 42 | M19: 5.25 | N19: 0 | O19: 1 | P19: =(F19*0.5+G19/10+J19*6+L19/10+N19*6-O19*2)/E19 -> 11.584615 | Q19: =77/337*100 -> 22.848665 | R19: =7/23*100 -> 30.434783 | S19: =(7+679)/(3748+23)*100 -> 18.191461 | T19: 16.61 | U19: 22.361644 | V19: =6*12 -> 72
A20: Tyler Johnson | B20: Minnesota | C20: 161 | D20: TB | E20: 13 | F20: 86 | G20: 1318 | H20: =G20/E20 -> 101.38462 | I20: 15.33 | J20: 13 | K20: 1 | L20: -1 | M20: -1 | N20: 0 | O20: 2 | P20: =(F20*0.5+G20/10+J20*6+L20/10+N20*6-O20*2)/E20 -> 19.130769 | Q20: =86/212*100 -> 40.566038 | R20: =13/31*100 -> 41.935484 | S20: =(13+1318)/(3293+31)*100 -> 40.042118 | T20: 22.546 | U20: 21.726027 | V20: =6*12+2 -> 74
A21: Darnell Mooney | B21: Tulane | C21: 173 | D21: CHI | E21: 13 | F21: 48 | G21: 713 | H21: =G21/E21 -> 54.846154 | I21: ='2020'!$G21/'2020'!$F21 -> 14.854167 | J21: 5 | K21: 0 | L21: 0 | M21: 0 | N21: 0 | O21: 0 | P21: =(F21*0.5+G21/10+J21*6+L21/10+N21*6-O21*2)/E21 -> 9.6384615 | Q21: =48/197*100 -> 24.365482 | R21: =5/19*100 -> 26.315789 | S21: =(5+713)/(19+2679)*100 -> 26.612305 | T21: =48/350*100 -> 13.714286 | U21: 22.550685 | V21: =5*12+11 -> 71

Sheet 2021
A1: Player | B1: School | C1: Pick_Num | D1: Team | E1: GP | F1: Rec | G1: Rec_Yds | H1: Rec_Yds_Game | I1: YPC | J1: Rec_TDs | K1: Rush_Att | L1: Rush_Yds | M1: Rush_YPA | N1: Rush_TDs | O1: Fumbles | P1: Col_FPPG | Q1: Rec_Percentage | R1: TD_Percentage | S1: Dominator | T1: Vac_Tar | U1: Age | V1: Height | W1: Breakout Age
A2: Ja'Marr Chase | B2: LSU | C2: 5 | D2: CIN | E2: 14 | F2: 84 | G2: 1780 | H2: ='2021'!$G2/'2021'!$E2 -> 127.14286 | I2: 21.2 | J2: 20 | K2: 1 | L2: 5 | M2: 5 | N2: 0 | O2: 1 | P2: =(F2*0.5+G2/10+J2*6+L2/10+N2*6-O2*2)/E2 -> 24.178571 | Q2: 21 | R2: 35 | S2: 33 | T2: 32.7 | U2: 21.175342 | V2: =6*12 -> 72 | W2: 19.5
A3: Jaylen Waddle | B3: Alabama | C3: 6 | D3: MIA | E3: 6 | F3: 28 | G3: 591 | H3: ='2021'!$G3/'2021'!$E3 -> 98.5 | I3: 21.1 | J3: 4 | K3: 3 | L3: 12 | M3: 4 | N3: 0 | O3: 0 | P3: =(F3*0.5+G3/10+J3*6+L3/10+N3*6-O3*2)/E3 -> 16.383333 | Q3: 19 | R3: 21 | S3: 24 | T3: 14 | U3: 22.526027 | V3: =5*12+10 -> 70 | W3: 21.8
A4: DeVonta Smith | B4: Alabama | C4: 10 | D4: PHI | E4: 13 | F4: 117 | G4: 1856 | H4: ='2021'!$G4/'2021'!$E4 -> 142.76923 | I4: 15.9 | J4: 23 | K4: 4 | L4: 6 | M4: 1.5 | N4: 1 | O4: 0 | P4: =(F4*0.5+G4/10+J4*6+L4/10+N4*6-O4*2)/E4 -> 29.9 | Q4: 36 | R4: 55 | S4: 47 | T4: 13.3 | U4: 22.556164 | V4: =6*12+1 -> 73 | W4: 20.8
A5: Kadarius Toney | B5: Florida | C5: 20 | D5: NYG | E5: 11 | F5: 70 | G5: 984 | H5: ='2021'!$G5/'2021'!$E5 -> 89.454545 | I5: 14.1 | J5: 10 | K5: 19 | L5: 161 | M5: 8.5 | N5: 1 | O5: 1 | P5: =(F5*0.5+G5/10+J5*6+L5/10+N5*6-O5*2)/E5 -> 19.409091 | Q5: 24 | R5: 24 | S5: 23 | T5: 24.2 | U5: 22.268493 | V5: =6*12 -> 72 | W5: 21.6
A6: Rashod Bateman | B6: Minnesota | C6: 27 | D6: BAL | E6: 13 | F6: 60 | G6: 1219 | H6: ='2021'!$G6/'2021'!$E6 -> 93.769231 | I6: 20.3 | J6: 11 | K6: 0 | L6: 0 | M6: 0 | N6: 0 | O6: 0 | P6: =(F6*0.5+G6/10+J6*6+L6/10+N6*6-O6*2)/E6 -> 16.761538 | Q6: 28 | R6: 35 | S6: 36 | T6: 21.7 | U6: 21.515068 | V6: =6*12+2 -> 74 | W6: 18.8
A7: Elijah Moore | B7: Ole Miss | C7: 34 | D7: NYJ | E7: 8 | F7: 86 | G7: 1193 | H7: ='2021'!$G7/'2021'!$E7 -> 149.125 | I7: 13.9 | J7: 8 | K7: 14 | L7: 64 | M7: 4.6 | N7: 0 | O7: 1 | P7: =(F7*0.5+G7/10+J7*6+L7/10+N7*6-O7*2)/E7 -> 26.8375 | Q7: 45 | R7: 33 | S7: 38 | T7: 29.7 | U7: 21.10411 | V7: =5*12+9 -> 69 | W7: 19.4
A8: Rondale Moore | B8: Purdue | C8: 49 | D8: ARI | E8: 13 | F8: 114 | G8: 1258 | H8: ='2021'!$G8/'2021'!$E8 -> 96.769231 | I8: 11 | J8: 12 | K8: 21 | L8: 213 | M8: 10.1 | N8: 2 | O8: 2 | P8: =(F8*0.5+G8/10+J8*6+L8/10+N8*6-O8*2)/E8 -> 21.853846 | Q8: 34 | R8: 43 | S8: 37 | T8: 21 | U8: 20.90137 | V8: =5*12+9 -> 69 | W8: 18.2
A9: D'Wayne Eskridge | B9: Western Michigan | C9: 56 | D9: SEA | E9: 6 | F9: 33 | G9: 768 | H9: ='2021'!$G9/'2021'!$E9 -> 128 | I9: 23.3 | J9: 8 | K9: 2 | L9: 43 | M9: 21.5 | N9: 0 | O9: 1 | P9: =(F9*0.5+G9/10+J9*6+L9/10+N9*6-O9*2)/E9 -> 23.933333 | Q9: 33 | R9: 44 | S9: 44 | T9: 14.2 | U9: 24.117808 | V9: =5*12+9 -> 69 | W9: 20.5
A10: Tutu Atwell | B10: Louisville | C10: 57 | D10: LAR | E10: 13 | F10: 69 | G10: 1272 | H10: ='2021'!$G10/'2021'!$E10 -> 97.846154 | I10: 18.4 | J10: 12 | K10: 9 | L10: 33 | M10: 3.7 | N10: 0 | O10: 4 | P10: =(F10*0.5+G10/10+J10*6+L10/10+N10*6-O10*2)/E10 -> 17.615385 | Q10: 39 | R10: 38 | S10: 39 | T10: 22.2 | U10: 21.575342 | V10: =5*12+9 -> 69 | W10: 18.9
A11: Terrace Marshall | B11: LSU | C11: 59 | D11: CAR | E11: 7 | F11: 48 | G11: 731 | H11: ='2021'!$G11/'2021'!$E11 -> 104.42857 | I11: 15.2 | J11: 10 | K11: 0 | L11: 0 | M11: 0 | N11: 0 | O11: 1 | P11: =(F11*0.5+G11/10+J11*6+L11/10+N11*6-O11*2)/E11 -> 22.157143 | Q11: 28 | R11: 60 | S11: 46 | T11: 28.8 | U11: 20.90137 | V11: =6*12+3 -> 75 | W11: 19.2
A12: Josh Palmer | B12: Tennessee | C12: 77 | D12: LAC | E12: 10 | F12: 33 | G12: 475 | H12: ='2021'!$G12/'2021'!$E12 -> 47.5 | I12: 14.4 | J12: 4 | K12: 0 | L12: 0 | M12: 0 | N12: 0 | O12: 0 | P12: =(F12*0.5+G12/10+J12*6+L12/10+N12*6-O12*2)/E12 -> 8.8 | Q12: 18 | R12: 29 | S12: 25 | T12: 0 | U12: 21.616438 | V12: =6*12+2 -> 74 | W12: NA
A13: Dyami Brown | B13: North Carolina | C13: 82 | D13: WAS | E13: 11 | F13: 55 | G13: 1099 | H13: ='2021'!$G13/'2021'!$E13 -> 99.909091 | I13: 20 | J13: 8 | K13: 0 | L13: 0 | M13: 0 | N13: 0 | O13: 0 | P13: =(F13*0.5+G13/10+J13*6+L13/10+N13*6-O13*2)/E13 -> 16.854545 | Q13: 25 | R13: 28 | S13: 30 | T13: 11.4 | U13: 21.506849 | V13: =6*12+1 -> 73 | W13: 19.8
A14: Amari Rodgers | B14: Clemson | C14: 85 | D14: GB | E14: 12 | F14: 77 | G14: 1020 | H14: ='2021'!$G14/'2021'!$E14 -> 85 | I14: 13.2 | J14: 7 | K14: 0 | L14: 0 | M14: 0 | N14: 0 | O14: 2 | P14: =(F14*0.5+G14/10+J14*6+L14/10+N14*6-O14*2)/E14 -> 14.875 | Q14: 24 | R14: 23 | S14: 23 | T14: 18 | U14: 21.613699 | V14: =5*12+10 -> 70 | W14: 21
A15: Nico Collins | B15: Michigan | C15: 89 | D15: HOU | E15: 12 | F15: 37 | G15: 729 | H15: ='2021'!$G15/'2021'!$E15 -> 60.75 | I15: 19.7 | J15: 7 | K15: 0 | L15: 0 | M15: 0 | N15: 0 | O15: 0 | P15: =(F15*0.5+G15/10+J15*6+L15/10+N15*6-O15*2)/E15 -> 11.116667 | Q15: 18 | R15: 30 | S15: 27 | T15: 29.6 | U15: 22.128767 | V15: =6*12+4 -> 76 | W15: 19.5
A16: Anthony Schwartz | B16: Auburn | C16: 91 | D16: CLE | E16: 10 | F16: 54 | G16: 636 | H16: ='2021'!$G16/'2021'!$E16 -> 63.6 | I16: 11.8 | J16: 3 | K16: 4 | L16: -6 | M16: -1.5 | N16: 0 | O16: 1 | P16: =(F16*0.5+G16/10+J16*6+L16/10+N16*6-O16*2)/E16 -> 10.6 | Q16: 28 | R16: 28 | S16: 28 | T16: 20.2 | U16: 20.660274 | V16: =6*12 -> 72 | W16: 20
A17: Dez Fitzpatrick | B17: Louisville | C17: 109 | D17: TEN | E17: 11 | F17: 43 | G17: 833 | H17: ='2021'!$G17/'2021'!$E17 -> 75.727273 | I17: 19.4 | J17: 3 | K17: 0 | L17: 0 | M17: 0 | N17: 0 | O17: 1 | P17: =(F17*0.5+G17/10+J17*6+L17/10+N17*6-O17*2)/E17 -> 10.981818 | Q17: 21 | R17: 15 | S17: 23 | T17: 52.6 | U17: 23.380822 | V17: =6*12+2 -> 74 | W17: NA
A18: Amon-Ra St. Brown | B18: USC | C18: 112 | D18: DET | E18: 6 | F18: 41 | G18: 478 | H18: ='2021'!$G18/'2021'!$E18 -> 79.666667 | I18: 11.7 | J18: 7 | K18: 0 | L18: 0 | M18: 0 | N18: 0 | O18: 0 | P18: =(F18*0.5+G18/10+J18*6+L18/10+N18*6-O18*2)/E18 -> 18.383333 | Q18: 23 | R18: 41 | S18: 33 | T18: 80.2 | U18: 21.528767 | V18: =6*12+1 -> 73 | W18: 18.9
A19: Jaelon Darden | B19: North Texas | C19: 129 | D19: TB | E19: 9 | F19: 74 | G19: 1190 | H19: ='2021'!$G19/'2021'!$E19 -> 132.22222 | I19: 16.1 | J19: 19 | K19: 2 | L19: -1 | M19: -0.5 | N19: 0 | O19: 0 | P19: =(F19*0.5+G19/10+J19*6+L19/10+N19*6-O19*2)/E19 -> 29.988889 | Q19: 44 | R19: 75 | S19: 61 | T19: 0 | U19: 22.30411 | V19: =5*12+9 -> 69 | W19: 20.6
A20: Tylan Wallace | B20: Oklahoma State | C20: 131 | D20: BAL | E20: 10 | F20: 59 | G20: 917 | H20: ='2021'!$G20/'2021'!$E20 -> 91.7 | I20: 15.5 | J20: 6 | K20: 1 | L20: 7 | M20: 7 | N20: 0 | O20: 0 | P20: =(F20*0.5+G20/10+J20*6+L20/10+N20*6-O20*2)/E20 -> 15.79 | Q20: 31 | R20: 37 | S20: 37 | T20: 21.7 | U20: 21.978082 | V20: =6*12 -> 72 | W20: 19.3
A21: Ihmir Smith-Marsette | B21: Iowa | C21: 157 | D21: MIN | E21: 7 | F21: 25 | G21: 345 | H21: ='2021'!$G21/'2021'!$E21 -> 49.285714 | I21: 13.8 | J21: 4 | K21: 7 | L21: 54 | M21: 7.7 | N21: 1 | O21: 1 | P21: =(F21*0.5+G21/10+J21*6+L21/10+N21*6-O21*2)/E21 -> 11.485714 | Q21: 20 | R21: 51 | S21: 37 | T21: 10.5 | U21: 21.682192 | V21: =6*12+1 -> 73 | W21: 20
A22: Simi Fehoko | B22: Stanford | C22: 179 | D22: DAL | E22: 6 | F22: 37 | G22: 584 | H22: ='2021'!$G22/'2021'!$E22 -> 97.333333 | I22: 15.8 | J22: 3 | K22: 1 | L22: -1 | M22: -1 | N22: 0 | O22: 0 | P22: =(F22*0.5+G22/10+J22*6+L22/10+N22*6-O22*2)/E22 -> 15.8 | Q22: 26 | R22: 43 | S22: 38 | T22: 0 | U22: 23.49589 | V22: =6*12+4 -> 76 | W22: 21.8
A23: Frank Darby | B23: Arizona State | C23: 187 | D23: ATL | E23: 12 | F23: 31 | G23: 616 | H23: ='2021'!$G23/'2021'!$E23 -> 51.333333 | I23: 19.9 | J23: 8 | K23: 0 | L23: 0 | M23: 0 | N23: 0 | O23: 0 | P23: =(F23*0.5+G23/10+J23*6+L23/10+N23*6-O23*2)/E23 -> 10.425 | Q23: 14 | R23: 41 | S23: 30 | T23: 6.3 | U23: 23.654795 | V23: =6*12+1 -> 73 | W23: NA
A24: Marquez Stevenson | B24: Houston | C24: 203 | D24: BUF | E24: 13 | F24: 75 | G24: 1019 | H24: ='2021'!$G24/'2021'!$E24 -> 78.384615 | I24: 13.6 | J24: 9 | K24: 14 | L24: 126 | M24: 9 | N24: 2 | O24: 3 | P24: =(F24*0.5+G24/10+J24*6+L24/10+N24*6-O24*2)/E24 -> 16.307692 | Q24: 26 | R24: 20 | S24: 23 | T24: 12.2 | U24: 23.109589 | V24: =6*12 -> 72 | W24: NA
A25: Shi Smith | B25: South Carolina | C25: 204 | D25: CAR | E25: 9 | F25: 57 | G25: 633 | H25: ='2021'!$G25/'2021'!$E25 -> 70.333333 | I25: 11.1 | J25: 4 | K25: 6 | L25: 6 | M25: 1 | N25: 0 | O25: 1 | P25: =(F25*0.5+G25/10+J25*6+L25/10+N25*6-O25*2)/E25 -> 12.711111 | Q25: 36 | R25: 56 | S25: 46 | T25: 28.8 | U25: 22.523288 | V25: =5*12+10 -> 70 | W25: 19.9
A26: Seth Williams | B26: Auburn | C26: 219 | D26: DEN | E26: 11 | F26: 47 | G26: 760 | H26: ='2021'!$G26/'2021'!$E26 -> 69.090909 | I26: 16.2 | J26: 4 | K26: 0 | L26: 0 | M26: 0 | N26: 0 | O26: 1 | P26: =(F26*0.5+G26/10+J26*6+L26/10+N26*6-O26*2)/E26 -> 11.045455 | Q26: 22 | R26: 33 | S26: 32 | T26: 0 | U26: 21.065753 | V26: =6*12+3 -> 75 | W26: 19.4
A27: Dazz Newsome | B27: North Carolina | C27: 221 | D27: CHI | E27: 12 | F27: 72 | G27: 1018 | H27: ='2021'!$G27/'2021'!$E27 -> 84.833333 | I27: 14.1 | J27: 10 | K27: 3 | L27: 9 | M27: 3 | N27: 0 | O27: 1 | P27: =(F27*0.5+G27/10+J27*6+L27/10+N27*6-O27*2)/E27 -> 16.391667 | Q27: 29 | R27: 28 | S27: 28 | T27: 67 | U27: 21.972603 | V27: =5*12+11 -> 71 | W27: 20.3
A28: Dax Milne | B28: BYU | C28: 258 | D28: WAS | E28: 12 | F28: 70 | G28: 1188 | H28: ='2021'!$G28/'2021'!$E28 -> 99 | I28: 17 | J28: 8 | K28: 11 | L28: 67 | M28: 6.1 | N28: 0 | O28: 2 | P28: =(F28*0.5+G28/10+J28*6+L28/10+N28*6-O28*2)/E28 -> 17.041667 | Q28: 26 | R28: 24 | S28: 26 | T28: 11.4 | U28: 21.865753 | V28: =6*12 -> 72 | W28: NA

Sheet 2022
A1: Player | B1: School | C1: Pick_Num | D1: Team | E1: GP | F1: Rec | G1: Rec_Yds | H1: Rec_Yds_Game | I1: YPC | J1: Rec_TDs | K1: Rush_Att | L1: Rush_Yds | M1: Rush_YPA | N1: Rush_TDs | O1: Fumbles | P1: Col_FPPG | Q1: Rec_Percentage | R1: TD_Percentage | S1: Dominator | T1: Vac_Tar | U1: Age | V1: Height | W1: Breakout Age
A2: Drake London | B2: USC | C2: 8 | D2: ATL | E2: 8 | F2: 88 | G2: 1084 | H2: =G2/E2 -> 135.5 | I2: 12.3 | J2: 7 | K2: 1 | L2: 2 | M2: 2 | N2: 0 | O2: 0 | P2: =(F2*0.5+G2/10+J2*6+L2/10+N2*6-O2*2)/E2 -> 24.325 | Q2: 45 | R2: 54 | S2: 51 | T2: 26 | U2: 20.775342 | V2: 77 | W2: 18.1
A3: Garrett Wilson | B3: Ohio State | C3: 10 | D3: NYJ | E3: 11 | F3: 70 | G3: 1058 | H3: =G3/E3 -> 96.181818 | I3: 15.1 | J3: 12 | K3: 4 | L3: 76 | M3: 19 | N3: 1 | O3: 0 | P3: =(F3*0.5+G3/10+J3*6+L3/10+N3*6-O3*2)/E3 -> 20.581818 | Q3: 24 | R3: 31 | S3: 28 | T3: 21 | U3: 21.780822 | V3: 72 | W3: 20.1
A4: Chris Olave | B4: Ohio State | C4: 11 | D4: NO | E4: 11 | F4: 65 | G4: 936 | H4: =G4/E4 -> 85.090909 | I4: 14.4 | J4: 13 | K4: 0 | L4: 0 | M4: 0 | N4: 0 | O4: 0 | P4: =(F4*0.5+G4/10+J4*6+L4/10+N4*6-O4*2)/E4 -> 18.554545 | Q4: 22 | R4: 33 | S4: 27 | T4: 13 | U4: 21.849315 | V4: 73 | W4: 19.2
A5: Jameson Williams | B5: Alabama | C5: 12 | D5: DET | E5: 15 | F5: 79 | G5: 1572 | H5: =G5/E5 -> 104.8 | I5: 19.9 | J5: 15 | K5: 3 | L5: 23 | M5: 7.7 | N5: 0 | O5: 2 | P5: =(F5*0.5+G5/10+J5*6+L5/10+N5*6-O5*2)/E5 -> 19 | Q5: 21 | R5: 31 | S5: 31 | T5: 5 | U5: 21.10411 | V5: 74 | W5: 20.4
A6: Jahan Dotson | B6: Penn State | C6: 16 | D6: WAS | E6: 12 | F6: 91 | G6: 1182 | H6: =G6/E6 -> 98.5 | I6: 13 | J6: 12 | K6: 6 | L6: 18 | M6: 3 | N6: 1 | O6: 1 | P6: =(F6*0.5+G6/10+J6*6+L6/10+N6*6-O6*2)/E6 -> 20.125 | Q6: 34 | R6: 52 | S6: 44 | T6: 20 | U6: 22.115068 | V6: 71 | W6: 20.5
A7: Treylon Burks | B7: Arkansas | C7: 18 | D7: TEN | E7: 12 | F7: 67 | G7: 1123 | H7: =G7/E7 -> 93.583333 | I7: 16.8 | J7: 11 | K7: 14 | L7: 112 | M7: 8 | N7: 1 | O7: 1 | P7: =(F7*0.5+G7/10+J7*6+L7/10+N7*6-O7*2)/E7 -> 18.916667 | Q7: 35 | R7: 54 | S7: 48 | T7: 43 | U7: 22.112329 | V7: 75 | W7: 20.5
A8: Christian Watson | B8: North Dakota State | C8: 34 | D8: GB | E8: 12 | F8: 43 | G8: 801 | H8: =G8/E8 -> 66.75 | I8: 18.6 | J8: 7 | K8: 15 | L8: 114 | M8: 7.6 | N8: 1 | O8: 0 | P8: =(F8*0.5+G8/10+J8*6+L8/10+N8*6-O8*2)/E8 -> 13.416667 | Q8: 0 | R8: 0 | S8: 0 | T8: 44 | U8: 22.978082 | V8: 77 | W8: NA
A9: Wan'Dale Robinson | B9: Kentucky | C9: 43 | D9: NYG | E9: 13 | F9: 104 | G9: 1334 | H9: =G9/E9 -> 102.61538 | I9: 12.8 | J9: 7 | K9: 7 | L9: 111 | M9: 15.9 | N9: 0 | O9: 1 | P9: =(F9*0.5+G9/10+J9*6+L9/10+N9*6-O9*2)/E9 -> 18.192308 | Q9: 43 | R9: 29 | S9: 37 | T9: 3 | U9: 21.323288 | V9: 71 | W9: 18.7
A10: John Metchie | B10: Alabama | C10: 44 | D10: HOU | E10: 13 | F10: 96 | G10: 1142 | H10: =G10/E10 -> 87.846154 | I10: 11.9 | J10: 8 | K10: 1 | L10: 8 | M10: 8 | N10: 0 | O10: 1 | P10: =(F10*0.5+G10/10+J10*6+L10/10+N10*6-O10*2)/E10 -> 16.076923 | Q10: 29 | R10: 19 | S10: 22 | T10: 8 | U10: 21.791781 | V10: 72 | W10: 21.1
A11: Tyquan Thornton | B11: Baylor | C11: 50 | D11: NE | E11: 14 | F11: 62 | G11: 948 | H11: =G11/E11 -> 67.714286 | I11: 15.3 | J11: 10 | K11: 1 | L11: -11 | M11: -11 | N11: 0 | O11: 0 | P11: =(F11*0.5+G11/10+J11*6+L11/10+N11*6-O11*2)/E11 -> 13.192857 | Q11: 26 | R11: 42 | S11: 37 | T11: 1 | U11: 21.736986 | V11: 75 | W11: NA
A12: George Pickens | B12: Georgia | C12: 52 | D12: PIT | E12: 12 | F12: 49 | G12: 727 | H12: =G12/E12 -> 60.583333 | I12: 14.8 | J12: 8 | K12: 0 | L12: 0 | M12: 0 | N12: 0 | O12: 0 | P12: =(F12*0.5+G12/10+J12*6+L12/10+N12*6-O12*2)/E12 -> 12.1 | Q12: 22 | R12: 36 | S12: 31 | T12: 21 | U12: 21.164384 | V12: 75 | W12: 18.5
A13: Alec Pierce | B13: Cincinnati | C13: 53 | D13: IND | E13: 14 | F13: 52 | G13: 884 | H13: =G13/E13 -> 63.142857 | I13: 17 | J13: 8 | K13: 0 | L13: 0 | M13: 0 | N13: 0 | O13: 0 | P13: =(F13*0.5+G13/10+J13*6+L13/10+N13*6-O13*2)/E13 -> 11.6 | Q13: 20 | R13: 24 | S13: 25 | T13: 26 | U13: 22.00274 | V13: 75 | W13: 20.3
A14: Skyy Moore | B14: Western Michigan | C14: 54 | D14: KC | E14: 12 | F14: 94 | G14: 1283 | H14: =G14/E14 -> 106.91667 | I14: 13.6 | J14: 10 | K14: 1 | L14: 10 | M14: 10 | N14: 0 | O14: 0 | P14: =(F14*0.5+G14/10+J14*6+L14/10+N14*6-O14*2)/E14 -> 19.691667 | Q14: 44 | R14: 47 | S14: 44 | T14: 41 | U14: 21.643836 | V14: 70 | W14: 20
A15: Velus Jones | B15: Tennessee | C15: 71 | D15: CHI | E15: 13 | F15: 62 | G15: 807 | H15: =G15/E15 -> 62.076923 | I15: 13 | J15: 7 | K15: 1 | L15: 15 | M15: 15 | N15: 0 | O15: 2 | P15: =(F15*0.5+G15/10+J15*6+L15/10+N15*6-O15*2)/E15 -> 11.630769 | Q15: 26 | R15: 21 | S15: 22 | T15: 31 | U15: 24.980822 | V15: 72 | W15: NA
A16: Jalen Tolbert | B16: South Alabama | C16: 88 | D16: DAL | E16: 12 | F16: 82 | G16: 1474 | H16: =G16/E16 -> 122.83333 | I16: 18 | J16: 8 | K16: 0 | L16: 0 | M16: 0 | N16: 0 | O16: 1 | P16: =(F16*0.5+G16/10+J16*6+L16/10+N16*6-O16*2)/E16 -> 19.533333 | Q16: 30 | R16: 36 | S16: 42 | T16: 32 | U16: 23.180822 | V16: 75 | W16: 20.5
A17: David Bell | B17: Purdue | C17: 99 | D17: CLE | E17: 11 | F17: 93 | G17: 1286 | H17: =G17/E17 -> 116.90909 | I17: 13.8 | J17: 6 | K17: 3 | L17: 39 | M17: 13 | N17: 0 | O17: 0 | P17: =(F17*0.5+G17/10+J17*6+L17/10+N17*6-O17*2)/E17 -> 19.545455 | Q17: 27 | R17: 20 | S17: 26 | T17: 27 | U17: 21.383562 | V17: 74 | W17: 18.7
A18: Danny Gray | B18: SMU | C18: 105 | D18: SF | E18: 10 | F18: 49 | G18: 803 | H18: =G18/E18 -> 80.3 | I18: 16.4 | J18: 9 | K18: 3 | L18: 40 | M18: 13.3 | N18: 0 | O18: 0 | P18: =(F18*0.5+G18/10+J18*6+L18/10+N18*6-O18*2)/E18 -> 16.28 | Q18: 20 | R18: 30 | S18: 29 | T18: 17 | U18: 23.090411 | V18: 73 | W18: NA
A19: Erik Ezukanma | B19: Texas Tech | C19: 125 | D19: MIA | E19: 11 | F19: 48 | G19: 705 | H19: =G19/E19 -> 64.090909 | I19: 14.7 | J19: 4 | K19: 10 | L19: 138 | M19: 13.8 | N19: 2 | O19: 0 | P19: =(F19*0.5+G19/10+J19*6+L19/10+N19*6-O19*2)/E19 -> 13.118182 | Q19: 23 | R19: 26 | S19: 25 | T19: 25 | U19: 22.271233 | V19: 75 | W19: 20.6
A20: Romeo Doubs | B20: Nevada | C20: 132 | D20: GB | E20: 11 | F20: 80 | G20: 1109 | H20: =G20/E20 -> 100.81818 | I20: 13.9 | J20: 11 | K20: 1 | L20: 4 | M20: 4 | N20: 0 | O20: 0 | P20: =(F20*0.5+G20/10+J20*6+L20/10+N20*6-O20*2)/E20 -> 19.754545 | Q20: 24 | R20: 34 | S20: 31 | T20: 44 | U20: 22.054795 | V20: 74 | W20: 19.4
A21: Calvin Austin | B21: Memphis | C21: 138 | D21: PIT | E21: 12 | F21: 74 | G21: 1149 | H21: =G21/E21 -> 95.75 | I21: 15.5 | J21: 8 | K21: 1 | L21: 69 | M21: 69 | N21: 1 | O21: 1 | P21: =(F21*0.5+G21/10+J21*6+L21/10+N21*6-O21*2)/E21 -> 17.566667 | Q21: 30 | R21: 33 | S21: 34 | T21: 21 | U21: 23.112329 | V21: 69 | W21: 21.5
A22: Khalil Shakir | B22: Boise State | C22: 148 | D22: BUF | E22: 12 | F22: 77 | G22: 1117 | H22: =G22/E22 -> 93.083333 | I22: 14.5 | J22: 7 | K22: 21 | L22: 130 | M22: 6.2 | N22: 0 | O22: 0 | P22: =(F22*0.5+G22/10+J22*6+L22/10+N22*6-O22*2)/E22 -> 17.1 | Q22: 30 | R22: 35 | S22: 35 | T22: 31 | U22: 22.246575 | V22: 72 | W22: 19.6
A23: Montrell Washington | B23: Samford | C23: 162 | D23: DEN | E23: 1 | F23: 10 | G23: 124 | H23: =G23/E23 -> 124 | I23: 12.4 | J23: 1 | K23: 3 | L23: 19 | M23: 6.3 | N23: 1 | O23: 1 | P23: =(F23*0.5+G23/10+J23*6+L23/10+N23*6-O23*2)/E23 -> 29.3 | Q23: 29 | R23: 33 | S23: 31 | T23: 1 | U23: 23.139726 | V23: 70 | W23: NA
A24: Kyle Philips | B24: UCLA | C24: 163 | D24: TEN | E24: 11 | F24: 59 | G24: 739 | H24: =G24/E24 -> 67.181818 | I24: 12.5 | J24: 10 | K24: 0 | L24: 0 | M24: 0 | N24: 0 | O24: 1 | P24: =(F24*0.5+G24/10+J24*6+L24/10+N24*6-O24*2)/E24 -> 14.672727 | Q24: 31 | R24: 47 | S24: 38 | T24: 43 | U24: 22.879452 | V24: 71 | W24: NA
A25: Jalen Nailor | B25: Michigan State | C25: 191 | D25: MIN | E25: 9 | F25: 37 | G25: 695 | H25: =G25/E25 -> 77.222222 | I25: 18.8 | J25: 6 | K25: 1 | L25: -3 | M25: -3 | N25: 0 | O25: 0 | P25: =(F25*0.5+G25/10+J25*6+L25/10+N25*6-O25*2)/E25 -> 13.744444 | Q25: 22 | R25: 32 | S25: 31 | T25: 3 | U25: 23.172603 | V25: 72 | W25: NA
A26: Michael Woods II | B26: Oklahoma | C26: 202 | D26: CLE | E26: 11 | F26: 35 | G26: 400 | H26: =G26/E26 -> 36.363636 | I26: 11.4 | J26: 2 | K26: 1 | L26: 2 | M26: 2 | N26: 0 | O26: 0 | P26: =(F26*0.5+G26/10+J26*6+L26/10+N26*6-O26*2)/E26 -> 6.3363636 | Q26: 15 | R26: 7 | S26: 10 | T26: 27 | U26: 22.123288 | V26: 73 | W26: NA
A27: Bo Melton | B27: Rutgers | C27: 229 | D27: SEA | E27: 10 | F27: 56 | G27: 619 | H27: =G27/E27 -> 61.9 | I27: 11.1 | J27: 3 | K27: 9 | L27: 51 | M27: 5.7 | N27: 0 | O27: 1 | P27: =(F27*0.5+G27/10+J27*6+L27/10+N27*6-O27*2)/E27 -> 11.1 | Q27: 32 | R27: 43 | S27: 39 | T27: 0 | U27: 22.961644 | V27: 71 | W27: NA
A28: Samori Toure | B28: Nebraska | C28: 258 | D28: GB | E28: 12 | F28: 46 | G28: 898 | H28: =G28/E28 -> 74.833333 | I28: 19.5 | J28: 5 | K28: 8 | L28: 63 | M28: 7.9 | N28: 1 | O28: 1 | P28: =(F28*0.5+G28/10+J28*6+L28/10+N28*6-O28*2)/E28 -> 12.758333 | Q28: 21 | R28: 36 | S28: 31 | T28: 44 | U28: 24.112329 | V28: 75 | W28: NA
A29: Justyn Ross | B29: Clemson | C29: Undrafted | D29: KC | E29: 10 | F29: 46 | G29: 514 | H29: =G29/E29 -> 51.4 | I29: 11.2 | J29: 3 | K29: 0 | L29: 0 | M29: 0 | N29: 0 | O29: 0 | P29: =(F29*0.5+G29/10+J29*6+L29/10+N29*6-O29*2)/E29 -> 9.24 | Q29: 26 | R29: 32 | S29: 29 | T29: 41 | U29: 22.383562 | V29: 76 | W29: 18.7
A30: Charleston Rambo | B30: Miami | C30: Undrafted | D30: CAR | E30: 12 | F30: 79 | G30: 1171 | H30: =G30/E30 -> 97.583333 | I30: 14.8 | J30: 7 | K30: 0 | L30: 0 | M30: 0 | N30: 0 | O30: 1 | P30: =(F30*0.5+G30/10+J30*6+L30/10+N30*6-O30*2)/E30 -> 16.383333 | Q30: 27 | R30: 23 | S30: 26 | T30: 1 | U30: 22.731507 | V30: 73 | W30: 22.1
A31: Dontario Drummond | B31: Ole Miss | C31: Undrafted | D31: DAL | E31: 12 | F31: 76 | G31: 1028 | H31: =G31/E31 -> 85.666667 | I31: 13.5 | J31: 8 | K31: 6 | L31: 40 | M31: 6.7 | N31: 1 | O31: 1 | P31: =(F31*0.5+G31/10+J31*6+L31/10+N31*6-O31*2)/E31 -> 16.4 | Q31: 29 | R31: 41 | S31: 36 | T31: 32 | U31: 24.69863 | V31: 73 | W31: 24

Sheet Sheet3
A1: Jordyn Tyson | B1: 42
A2: Carnell Tate | B2: 32
A3: Makai Lemon | B3: 39
A4: KC Concepcion | B4: 42
A5: Denzel Boston | B5: 41
A6: Omar Cooper Jr. | B6: 28
A7: Elijah Sarratt | B7: 33
A8: Germie Bernard | B8: 21
A9: Chris Brazzell II | B9: 33
A10: Chris Bell | B10: 38
A11: Ja'Kobi Lane | B11: 29
A12: Malachi Fields | B12: 20
... A46: Jeff Caldwell | B46: 19

Sheet 2024
A1: Player | B1: School | C1: Pick_Num | D1: Team | E1: GP | F1: Rec | G1: Rec_Yds | H1: Rec_Yds_Game | I1: YPC | J1: Rec_TDs | K1: Rush_Att | L1: Rush_Yds | M1: Rush_YPA | N1: Rush_TDs | O1: Fumbles | P1: Col_FPPG | Q1: Rec_Percentage | R1: TD_Percentage | S1: Dominator | T1: Vac_Tar | U1: Age | V1: Height | W1: Breakout Age
A2: Marvin Harrison Jr. | B2: Ohio State | C2: 4 | D2: ARI | E2: 12 | F2: 67 | G2: 1211 | H2: 100.91667 | I2: 18.1 | J2: 14 | K2: 2 | L2: 26 | M2: 13 | N2: 1 | O2: 0 | P2: 20.6 | Q2: 0.28 | R2: 0.58 | S2: 0.47 | T2: 19 | U2: 21.8 | V2: 75 | W2: 20.1
A3: Malik Nabers | B3: LSU | C3: 6 | D3: NYG | E3: 13 | F3: 89 | G3: 1569 | H3: 120.69231 | I3: 17.6 | J3: 14 | K3: 1 | L3: 1 | M3: 1 | N3: 0 | O3: 0 | P3: 21.961538 | Q3: 0.31 | R3: 0.32 | S3: 0.33 | T3: 11 | U3: 20.9 | V3: 72 | W3: 20.2
A4: Rome Odunze | B4: Washington | C4: 9 | D4: CHI | E4: 15 | F4: 92 | G4: 1640 | H4: 109.33333 | I4: 17.8 | J4: 13 | K4: 2 | L4: 37 | M4: 18.5 | N4: 1 | O4: 1 | P4: 19.713333 | Q4: 0.24 | R4: 0.34 | S4: 0.33 | T4: 14 | U4: 22 | V4: 75 | W4: 19.3
A5: Keon Coleman | B5: Florida State | C5: 33 | D5: BUF | E5: 12 | F5: 50 | G5: 658 | H5: 54.833333 | I5: 13.2 | J5: 11 | K5: 1 | L5: 2 | M5: 2 | N5: 0 | O5: 1 | P5: 12.916667 | Q5: 0.22 | R5: 0.51 | S5: 0.36 | T5: 52 | U5: 21 | V5: 75 | W5: 19.3
A6: Xavier Worthy | B6: Texas | C6: 28 | D6: KC | E6: 12 | F6: 63 | G6: 998 | H6: 83.166667 | I6: 15.8 | J6: 12 | K6: 1 | L6: 7 | M6: 7 | N6: 0 | O6: 2 | P6: 16.666667 | Q6: 0.29 | R6: 0.41 | S6: 0.39 | T6: 13 | U6: 21.1 | V6: 71 | W6: 18.4
A7: Ladd McConkey | B7: Georgia | C7: 34 | D7: LAC | E7: 15 | F7: 58 | G7: 762 | H7: 50.8 | I7: 13.1 | J7: 7 | K7: 7 | L7: 134 | M7: 19.1 | N7: 2 | O7: 3 | P7: 11.106667 | Q7: 0.17 | R7: 0.23 | S7: 0.19 | T7: 40 | U7: 22.5 | V7: 72 | W7: NA
A8: Adonai Mitchell | B8: Texas | C8: 52 | D8: IND | E8: 14 | F8: 55 | G8: 845 | H8: 60.357143 | I8: 15.4 | J8: 11 | K8: 2 | L8: 1 | M8: 0.5 | N8: 0 | O8: 1 | P8: 12.578571 | Q8: 0.17 | R8: 0.44 | S8: 0.32 | T8: 3 | U8: 22.6 | V8: 74 | W8: 21.9
A9: Brian Thomas Jr. | B9: LSU | C9: 23 | D9: JAX | E9: 13 | F9: 68 | G9: 1177 | H9: 90.538462 | I9: 17.3 | J9: 17 | K9: 1 | L9: -6 | M9: -6 | N9: 0 | O9: 0 | P9: 19.469231 | Q9: 0.24 | R9: 0.39 | S9: 0.32 | T9: 36 | U9: 21.6 | V9: 76 | W9: 20.9
A10: Xavier Legette | B10: South Carolina | C10: 32 | D10: CAR | E10: 12 | F10: 71 | G10: 1255 | H10: 104.58333 | I10: 17.7 | J10: 7 | K10: 9 | L10: -9 | M10: -1 | N10: 0 | O10: 0 | P10: 16.841667 | Q10: 0.25 | R10: 0.33 | S10: 0.35 | T10: 14 | U10: 23.3 | V10: 73 | W10: 22.6
A11: Ja'Lynn Polk | B11: Washington | C11: 37 | D11: NE | E11: 13 | F11: 69 | G11: 1159 | H11: 89.153846 | I11: 16.8 | J11: 9 | K11: 4 | L11: 32 | M11: 8 | N11: 1 | O11: 0 | P11: 16.430769 | Q11: 0.21 | R11: 0.27 | S11: 0.26 | T11: 10 | U11: 22.1 | V11: 73 | W11: 19.4
A12: Roman Wilson | B12: Michigan | C12: 84 | D12: PIT | E12: 14 | F12: 48 | G12: 789 | H12: 56.357143 | I12: 16.4 | J12: 12 | K12: 1 | L12: 10 | M12: 10 | N12: 0 | O12: 0 | P12: 12.564286 | Q12: 0.2 | R12: 0.54 | S12: 0.39 | T12: 19 | U12: 22.9 | V12: 71 | W12: 22.2
A13: Troy Franklin | B13: Oregon | C13: 102 | D13: DEN | E13: 13 | F13: 81 | G13: 1383 | H13: 106.38462 | I13: 17.1 | J13: 14 | K13: 0 | L13: 0 | M13: 0 | N13: 0 | O13: 0 | P13: 20.215385 | Q13: 0.22 | R13: 0.31 | S13: 0.3 | T13: 18 | U13: 21.3 | V13: 74 | W13: 19.6
A14: Devontez Walker | B14: North Carolina | C14: 113 | D14: BAL | E14: 12 | F14: 58 | G14: 921 | H14: 76.75 | I14: 15.9 | J14: 11 | K14: 3 | L14: 29 | M14: 9.7 | N14: 1 | O14: 0 | P14: 16.333333 | Q14: 0.3 | R14: 0.65 | S14: 0.5 | T14: 17 | U14: 22.9 | V14: 74 | W14: 21.2
A15: Jermaine Burton | B15: Alabama | C15: 80 | D15: CIN | E15: 12 | F15: 39 | G15: 798 | H15: 66.5 | I15: 20.5 | J15: 8 | K15: 0 | L15: 0 | M15: 0 | N15: 0 | O15: 0 | P15: 12.275 | Q15: 0.22 | R15: 0.41 | S15: 0.35 | T15: 17 | U15: 22.9 | V15: 72 | W15: 22.2
A16: Ricky Pearsall | B16: Florida | C16: 31 | D16: SF | E16: 12 | F16: 64 | G16: 970 | H16: 80.833333 | I16: 15.2 | J16: 4 | K16: 3 | L16: 62 | M16: 20.7 | N16: 2 | O16: 0 | P16: 14.266667 | Q16: 0.23 | R16: 0.2 | S16: 0.25 | T16: 11 | U16: 23.7 | V16: 73 | W16: 21
A17: Johnny Wilson | B17: Florida State | C17: 185 | D17: PHI | E17: 12 | F17: 43 | G17: 897 | H17: 74.75 | I17: 20.9 | J17: 5 | K17: 0 | L17: 0 | M17: 0 | N17: 0 | O17: 0 | P17: 11.766667 | Q17: 0.19 | R17: 0.19 | S17: 0.23 | T17: 12 | U17: 23.1 | V17: 78 | W17: 21.4
A18: Tahj Washington | B18: USC | C18: 241 | D18: MIA | E18: 13 | F18: 59 | G18: 1062 | H18: 81.692308 | I18: 18 | J18: 8 | K18: 1 | L18: 10 | M18: 10 | N18: 0 | O18: 0 | P18: 14.207692 | Q18: 0.19 | R18: 0.22 | S18: 0.23 | T18: 8 | U18: 23 | V18: 70 | W18: 19.3
A19: Cornelius Johnson | B19: Michigan | C19: 253 | D19: LAC | E19: 13 | F19: 32 | G19: 499 | H19: 38.384615 | I19: 15.6 | J19: 6 | K19: 0 | L19: 0 | M19: 0 | N19: 0 | O19: 1 | P19: 7.6846154 | Q19: 0.14 | R19: 0.28 | S19: 0.22 | T19: 40 | U19: 23.5 | V19: 75 | W19: 19.8
... A31: Javon Baker | B31: UCF | C31: 110 | D31: NE | E31: 13 | F31: 52 | G31: 1140 | H31: 87.692308 | I31: 21.9 | J31: 7 | K31: 0 | L31: 0 | M31: 0 | N31: 0 | O31: 0 | P31: 14 | Q31: 0.23 | R31: 0.29 | S31: 0.31 | T31: 10 | U31: 22.3 | V31: 73 | W31: 20.5

Sheet 2025
A1: Player | B1: School | C1: Pick_Num | D1: Team | E1: GP | F1: Rec | G1: Rec_Yds | H1: Rec_Yds_Game | I1: YPC | J1: Rec_TDs | K1: Rush_Att | L1: Rush_Yds | M1: Rush_YPA | N1: Rush_TDs | O1: Fumbles | P1: Col_FPPG | Q1: Rec_Percentage | R1: TD_Percentage | S1: Dominator | T1: Vac_Tar | U1: Age | V1: Height | W1: Breakout Age
A2: Travis Hunter | B2: Colorado | C2: 2 | D2: JAX | E2: 13 | F2: 96 | G2: 1258 | H2: =G2/E2 -> 96.769231 | I2: 13.1 | J2: 15 | K2: 2 | L2: 5 | M2: 2.5 | N2: 1 | O2: 0 | P2: =(F2*0.5+G2/10+J2*6+L2/10+N2*6-O2*2)/E2 -> 20.792308 | Q2: 27 | R2: 41 | S2: 35 | T2: 13 | U2: 21.9 | V2: 73 | W2: 20.3
A3: Tetairoa McMillan | B3: Arizona | C3: 8 | D3: CAR | E3: 12 | F3: 84 | G3: 1319 | H3: =G3/E3 -> 109.91667 | I3: 15.7 | J3: 8 | K3: 0 | L3: 0 | M3: 0 | N3: 0 | O3: 1 | P3: =(F3*0.5+G3/10+J3*6+L3/10+N3*6-O3*2)/E3 -> 18.325 | Q3: 32 | R3: 44 | S3: 44 | T3: 29 | U3: 22.1 | V3: 76 | W3: 19.4
A4: Emeka Egbuka | B4: Ohio State | C4: 19 | D4: TB | E4: 13 | F4: 74 | G4: 1151 | H4: =G4/E4 -> 88.538462 | I4: 15.6 | J4: 10 | K4: 11 | L4: 87 | M4: 7.9 | N4: 2 | O4: 1 | P4: =(F4*0.5+G4/10+J4*6+L4/10+N4*6-O4*2)/E4 -> 17.753846 | Q4: 27 | R4: 24 | S4: 26 | T4: 0 | U4: 22.5 | V4: 73 | W4: 19.9
A5: Matthew Golden | B5: Texas | C5: 23 | D5: GB | E5: 16 | F5: 58 | G5: 987 | H5: =G5/E5 -> 61.6875 | I5: 17 | J5: 9 | K5: 0 | L5: 0 | M5: 0 | N5: 0 | O5: 0 | P5: =(F5*0.5+G5/10+J5*6+L5/10+N5*6-O5*2)/E5 -> 11.35625 | Q5: 16 | R5: 23 | S5: 22 | T5: 4 | U5: 21.7 | V5: 71 | W5: 20.1
A6: Jayden Higgins | B6: Iowa State | C6: 34 | D6: HOU | E6: 13 | F6: 87 | G6: 1183 | H6: =G6/E6 -> 91 | I6: 13.6 | J6: 9 | K6: 0 | L6: 0 | M6: 0 | N6: 0 | O6: 0 | P6: =(F6*0.5+G6/10+J6*6+L6/10+N6*6-O6*2)/E6 -> 16.6 | Q6: 34 | R6: 39 | S6: 37 | T6: 18 | U6: 22.4 | V6: 76 | W6: 20.7
A7: Luther Burden | B7: Missouri | C7: 39 | D7: CHI | E7: 13 | F7: 86 | G7: 1212 | H7: =G7/E7 -> 93.230769 | I7: 14.1 | J7: 9 | K7: 7 | L7: 31 | M7: 4.4 | N7: 0 | O7: 0 | P7: =(F7*0.5+G7/10+J7*6+L7/10+N7*6-O7*2)/E7 -> 17.023077 | Q7: 35 | R7: 39 | S7: 37 | T7: 23 | U7: 21.4 | V7: 72 | W7: 18.7
A8: Tre Harris | B8: Ole Miss | C8: 55 | D8: LAC | E8: 9 | F8: 60 | G8: 1030 | H8: =G8/E8 -> 114.44444 | I8: 17.2 | J8: 7 | K8: 0 | L8: 0 | M8: 0 | N8: 0 | O8: 2 | P8: =(F8*0.5+G8/10+J8*6+L8/10+N8*6-O8*2)/E8 -> 19 | Q8: 29 | R8: 33 | S8: 32 | T8: 18 | U8: 23.2 | V8: 75 | W8: 20.5
A9: Jack Bech | B9: TCU | C9: 58 | D9: LV | E9: 12 | F9: 62 | G9: 1034 | H9: =G9/E9 -> 86.166667 | I9: 16.7 | J9: 9 | K9: 0 | L9: 7 | M9: 0 | N9: 0 | O9: 0 | P9: =(F9*0.5+G9/10+J9*6+L9/10+N9*6-O9*2)/E9 -> 15.758333 | Q9: 21 | R9: 34 | S9: 30 | T9: 7 | U9: 22.4 | V9: 73 | W9: 21.7
A10: Kyle Williams | B10: Washington State | C10: 69 | D10: NE | E10: 13 | F10: 70 | G10: 1198 | H10: =G10/E10 -> 92.153846 | I10: 17.1 | J10: 14 | K10: 9 | L10: 57 | M10: 6.3 | N10: 0 | O10: 1 | P10: =(F10*0.5+G10/10+J10*6+L10/10+N10*6-O10*2)/E10 -> 18.653846 | Q10: 27 | R10: 42 | S10: 37 | T10: 0 | U10: 22.8 | V10: 71 | W10: 18.1
A11: Isaac TeSlaa | B11: Arkansas | C11: 70 | D11: DET | E11: 10 | F11: 28 | G11: 545 | H11: =G11/E11 -> 54.5 | I11: 19.5 | J11: 3 | K11: 0 | L11: 0 | M11: 0 | N11: 0 | O11: 1 | P11: =(F11*0.5+G11/10+J11*6+L11/10+N11*6-O11*2)/E11 -> 8.45 | Q11: 14 | R11: 24 | S11: 22 | T11: 1 | U11: 23 | V11: 76 | W11: 22.3
A12: Pat Bryant | B12: Illinois | C12: 74 | D12: DEN | E12: 12 | F12: 53 | G12: 978 | H12: =G12/E12 -> 81.5 | I12: 18.5 | J12: 10 | K12: 5 | L12: 14 | M12: 2.8 | N12: 0 | O12: 0 | P12: =(F12*0.5+G12/10+J12*6+L12/10+N12*6-O12*2)/E12 -> 15.475 | Q12: 27 | R12: 49 | S12: 43 | T12: 11 | U12: 22.4 | V12: 74 | W12: 20.7
A13: Jaylin Noel | B13: Iowa State | C13: 79 | D13: HOU | E13: 14 | F13: 81 | G13: 1194 | H13: =G13/E13 -> 85.285714 | I13: 14.7 | J13: 8 | K13: 9 | L13: 38 | M13: 4.2 | N13: 0 | O13: 2 | P13: =(F13*0.5+G13/10+J13*6+L13/10+N13*6-O13*2)/E13 -> 14.835714 | Q13: 29 | R13: 32 | S13: 32 | T13: 18 | U13: 22.6 | V13: 70 | W13: 21
... A31: Dominic Lovett | B31: Georgia | C31: 244 | D31: DET | E31: 12 | F31: 56 | G31: 846 | H31: =G31/E31 -> 70.5 | I31: 15.1 | J31: 3 | K31: 7 | L31: 6 | M31: 0.9 | N31: 0 | O31: 1 | P31: =(F31*0.5+G31/10+J31*6+L31/10+N31*6-O31*2)/E31 -> 10.766667 | Q31: 24 | R31: 25 | S31: 29 | T31: 1 | U31: 22.5 | V31: 70 | W31: 19.8
A32: Isaiah Bond | B32: Texas | C32: N/A | D32: CLE | E32: 13 | F32: 34 | G32: 540 | H32: =G32/E32 -> 41.538462 | I32: 15.9 | J32: 5 | K32: 4 | L32: 98 | M32: 24.5 | N32: 1 | O32: 0 | P32: =(F32*0.5+G32/10+J32*6+L32/10+N32*6-O32*2)/E32 -> 8.9846154 | Q32: 12 | R32: 15 | S32: 15 | T32: 16 | U32: 21.1 | V32: 71 | W32: 21.1
A33: Theo Wease Jr. | B33: Missouri | C33: N/A | D33: MIA | E33: 13 | F33: 60 | G33: 884 | H33: =G33/E33 -> 68 | I33: 14.7 | J33: 4 | K33: 0 | L33: 0 | M33: 0 | N33: 0 | O33: 0 | P33: =(F33*0.5+G33/10+J33*6+L33/10+N33*6-O33*2)/E33 -> 10.953846 | Q33: 24 | R33: 29 | S33: 29 | T33: 4 | U33: 23.8 | V33: 74 | W33: 21.2
A34: Xavier Restrepo | B34: Miami | C34: NA | D34: TEN | E34: 12 | F34: 69 | G34: 1127 | H34: =G34/E34 -> 93.916667 | I34: 16.3 | J34: 11 | K34: 0 | L34: 0 | M34: 0 | N34: 0 | O34: 2 | P34: =(F34*0.5+G34/10+J34*6+L34/10+N34*6-O34*2)/E34 -> 17.433333 | Q34: 23 | R34: 29 | S34: 28 | T34: 16 | U34: 23 | V34: 70 | W34: 21.4
A35: Isaiah Neyor | B35: Nebraska | C35: N/A | D35: SF | E35: 13 | F35: 44 | G35: 878 | H35: =G35/E35 -> 67.538462 | I35: 20 | J35: 12 | K35: 12 | L35: 23 | M35: 1.9 | N35: 1 | O35: 2 | P35: =(F35*0.5+G35/10+J35*6+L35/10+N35*6-O35*2)/E35 -> 14.315385 | Q35: 27 | R35: 80 | S35: 60 | T35: 16 | U35: 23.9 | V35: 76 | W35: 19.2
A36: Josh Kelly | B36: Texas Tech | C36: N/A | D36: DAL | E36: 12 | F36: 61 | G36: 923 | H36: =G36/E36 -> 76.916667 | I36: 15.1 | J36: 8 | K36: 1 | L36: 3 | M36: 3 | N36: 0 | O36: 0 | P36: =(F36*0.5+G36/10+J36*6+L36/10+N36*6-O36*2)/E36 -> 14.258333 | Q36: 18 | R36: 30 | S36: 26 | T36: 10 | U36: 23.8 | V36: 73 | W36: 22.2
A37: Nick Nash | B37: San Jose State | C37: N/A | D37: ATL | E37: 12 | F37: 104 | G37: 1382 | H37: =G37/E37 -> 115.16667 | I37: 13.3 | J37: 16 | K37: 1 | L37: -9 | M37: -9 | N37: 0 | O37: 3 | P37: =(F37*0.5+G37/10+J37*6+L37/10+N37*6-O37*2)/E37 -> 23.275 | Q37: 36 | R37: 56 | S37: 45 | T37: 2 | U37: 24.7 | V37: 75 | W37: 23.1
A38: Da'Quan Felton | B38: Virginia Tech | C38: N/A | D38: NYG | E38: 10 | F38: 38 | G38: 667 | H38: =G38/E38 -> 66.7 | I38: 17.6 | J38: 8 | K38: 0 | L38: 0 | M38: 0 | N38: 0 | O38: 0 | P38: =(F38*0.5+G38/10+J38*6+L38/10+N38*6-O38*2)/E38 -> 13.37 | Q38: 24 | R38: 45 | S38: 39 | T38: 0 | U38: 24.3 | V38: 77 | W38: 21.6
A39: Traeshon Holden | B39: Oregon | C39: N/A | D39: DAL | E39: 13 | F39: 45 | G39: 718 | H39: =G39/E39 -> 55.230769 | I39: 16 | J39: 5 | K39: 2 | L39: 22 | M39: 11 | N39: 0 | O39: 1 | P39: =(F39*0.5+G39/10+J39*6+L39/10+N39*6-O39*2)/E39 -> 9.5769231 | Q39: 14 | R39: 18 | S39: 18 | T39: 10 | U39: 23.7 | V39: 74 | W39: 23.7
A40: Elijhah Badger | B40: Florida | C40: N/A | D40: KC | E40: 12 | F40: 70 | G40: 866 | H40: =G40/E40 -> 72.166667 | I40: 12.4 | J40: 7 | K40: 4 | L40: 23 | M40: 5.8 | N40: 0 | O40: 1 | P40: =(F40*0.5+G40/10+J40*6+L40/10+N40*6-O40*2)/E40 -> 13.658333 | Q40: 26 | R40: 39 | S40: 33 | T40: 19 | U40: 23.7 | V40: 73 | W40: 21.1
A41: Kobe Hudson | B41: UCF | C41: N/A | D41: CAR | E41: 13 | F41: 44 | G41: 900 | H41: =G41/E41 -> 69.230769 | I41: 20.5 | J41: 8 | K41: 1 | L41: -8 | M41: -8 | N41: 0 | O41: 0 | P41: =(F41*0.5+G41/10+J41*6+L41/10+N41*6-O41*2)/E41 -> 12.246154 | Q41: 19 | R41: 33 | S41: 30 | T41: 29 | U41: 22.6 | V41: 73 | W41: 19
A42: Sam Brown Jr. | B42: Miami | C42: N/A | D42: GB | E42: 11 | F42: 61 | G42: 815 | H42: =G42/E42 -> 74.090909 | I42: 13.4 | J42: 3 | K42: 0 | L42: 0 | M42: 0 | N42: 0 | O42: 0 | P42: =(F42*0.5+G42/10+J42*6+L42/10+N42*6-O42*2)/E42 -> 11.818182 | Q42: 26 | R42: 14 | S42: 22 | T42: 4 | U42: 22.7 | V42: 74 | W42: 20.1
A43: Antwane Wells Jr. | B43: Ole Miss | C43: N/A | D43: NYG | E43: 12 | F43: 68 | G43: 928 | H43: =G43/E43 -> 77.333333 | I43: 13.6 | J43: 6 | K43: 3 | L43: 10 | M43: 3.3 | N43: 1 | O43: 3 | P43: =(F43*0.5+G43/10+J43*6+L43/10+N43*6-O43*2)/E43 -> 13.65 | Q43: 26 | R43: 28 | S43: 29 | T43: 0 | U43: 24.1 | V43: 73 | W43: 21.4
... A46: Beaux Collins | B46: Notre Dame | C46: N/A | D46: NYG | E46: 10 | F46: 38 | G46: 510 | H46: =G46/E46 -> 51 | I46: 13.4 | J46: 3 | K46: 0 | L46: 0 | M46: 0 | N46: 0 | O46: 0 | P46: =(F46*0.5+G46/10+J46*6+L46/10+N46*6-O46*2)/E46 -> 8.8 | Q46: 16 | R46: 19 | S46: 20 | T46: 0 | U46: 22.4 | V46: 75 | W46: 18.7
A47: Ja'Corey Brooks | B47: Louisville | C47: N/A | D47: WAS | E47: 12 | F47: 61 | G47: 1013 | H47: =G47/E47 -> 84.416667 | I47: 16.6 | J47: 9 | K47: 0 | L47: 0 | M47: 0 | N47: 0 | O47: 0 | P47: =(F47*0.5+G47/10+J47*6+L47/10+N47*6-O47*2)/E47 -> 15.483333 | Q47: 24 | R47: 38 | S47: 34 | T47: 24 | U47: - | V47: 74 | W47: -
A48: Roc Taylor | B48: Memphis | C48: N/A | D48: PIT | E48: 13 | F48: 69 | G48: 1083 | H48: =G48/E48 -> 83.307692 | I48: 15.7 | J48: 4 | K48: 2 | L48: 2 | M48: 1 | N48: 0 | O48: 0 | P48: =(F48*0.5+G48/10+J48*6+L48/10+N48*6-O48*2)/E48 -> 12.846154 | Q48: 22 | R48: 12 | S48: 19 | T48: 13 | U48: 22.2 | V48: 74 | W48: 22.2
A49: Andrew Armstrong | B49: Arkansas | C49: N/A | D49: MIA | E49: 11 | F49: 78 | G49: 1140 | H49: =G49/E49 -> 103.63636 | I49: 14.6 | J49: 1 | K49: 0 | L49: 0 | M49: 0 | N49: 0 | O49: 1 | P49: =(F49*0.5+G49/10+J49*6+L49/10+N49*6-O49*2)/E49 -> 14.272727 | Q49: 36 | R49: 7 | S49: 22 | T49: 4 | U49: 24.5 | V49: 76 | W49: 22.8

Sheet 2026
A1: Player | B1: School | C1: Pick_Num | D1: Team | E1: GP | F1: Rec | G1: Rec_Yds | H1: Rec_Yds_Game | I1: YPC | J1: Rec_TDs | K1: Rush_Att | L1: Rush_Yds | M1: Rush_YPA | N1: Rush_TDs | O1: Fumbles | P1: Col_FPPG | Q1: Rec_Percentage | R1: TD_Percentage | S1: Dominator | T1: Vac_Tar | U1: Age | V1: Height | W1: Breakout Age
A2: Jordyn Tyson | B2: Arizona State | E2: 12 | F2: 75 | G2: 1101 | H2: =G2/E2 -> 91.75 | I2: 14.7 | J2: 10 | K2: 1 | L2: 1 | M2: 1 | N2: 0 | O2: 2 | P2: =(F2*0.5+G2/10+J2*6+L2/10+N2*6-O2*2)/E2 -> 16.975 | Q2: 37 | R2: 45 | S2: 42 | U2: 21.7 | V2: 74 | W2: 18.1
A3: Carnell Tate | B3: Ohio State | E3: 11 | F3: 51 | G3: 875 | H3: =G3/E3 -> 79.545455 | I3: 17.2 | J3: 9 | K3: 2 | L3: 16 | M3: 8 | N3: 0 | O3: 0 | P3: =(F3*0.5+G3/10+J3*6+L3/10+N3*6-O3*2)/E3 -> 15.327273 | Q3: 21 | R3: 35 | S3: 32 | U3: 21.2 | V3: 74 | W3: 20.6
A4: Makai Lemon | B4: USC | E4: 12 | F4: 79 | G4: 1156 | H4: =G4/E4 -> 96.333333 | I4: 14.6 | J4: 11 | K4: 9 | L4: 4 | M4: 0.4 | N4: 2 | O4: 1 | P4: =(F4*0.5+G4/10+J4*6+L4/10+N4*6-O4*2)/E4 -> 19.291667 | Q4: 31 | R4: 46 | S4: 39 | U4: 21.8 | V4: 71 | W4: 21.3
A5: KC Concepcion | B5: Texas A&M | E5: 13 | F5: 71 | G5: 839 | H5: =G5/E5 -> 64.538462 | I5: 11.8 | J5: 10 | K5: 41 | L5: 320 | M5: 7.8 | N5: 0 | O5: 0 | P5: =(F5*0.5+G5/10+J5*6+L5/10+N5*6-O5*2)/E5 -> 16.261538 | Q5: 32 | R5: 53 | S5: 42 | U5: 21.4 | V5: 72 | W5: 18.8
A6: Denzel Boston | B6: Washington | E6: 11 | F6: 62 | G6: 881 | H6: =G6/E6 -> 80.090909 | I6: 14.2 | J6: 11 | K6: 0 | L6: 0 | M6: 0 | N6: 0 | O6: 1 | P6: =(F6*0.5+G6/10+J6*6+L6/10+N6*6-O6*2)/E6 -> 16.645455 | Q6: 29 | R6: 50 | S6: 41 | U6: 22.3 | V6: 76 | W6: 20.8
A7: Omar Cooper Jr. | B7: Indiana | E7: 15 | F7: 70 | G7: 961 | H7: =G7/E7 -> 64.066667 | I7: 13.7 | J7: 13 | K7: 3 | L7: 74 | M7: 24.7 | N7: 1 | O7: 0 | P7: =(F7*0.5+G7/10+J7*6+L7/10+N7*6-O7*2)/E7 -> 14.833333 | Q7: 26 | R7: 30 | S7: 28 | U7: 22.3 | V7: 72 | W7: 20.7
A8: Elijah Sarratt | B8: Indiana | E8: 13 | F8: 64 | G8: 806 | H8: =G8/E8 -> 62 | I8: 12.6 | J8: 15 | K8: 0 | L8: 0 | M8: 0 | N8: 0 | O8: 0 | P8: =(F8*0.5+G8/10+J8*6+L8/10+N8*6-O8*2)/E8 -> 15.584615 | Q8: 27 | R8: 40 | S8: 33 | U8: 22.9 | V8: 75 | W8: 20.3
A9: Germie Bernard | B9: Alabama | E9: 15 | F9: 64 | G9: 862 | H9: =G9/E9 -> 57.466667 | I9: 13.5 | J9: 7 | K9: 18 | L9: 101 | M9: 5.6 | N9: 2 | O9: 0 | P9: =(F9*0.5+G9/10+J9*6+L9/10+N9*6-O9*2)/E9 -> 12.153333 | Q9: 19 | R9: 22 | S9: 21 | U9: 22.4 | V9: 73 | W9: 21.8
A10: Chris Brazzell II | B10: Tennessee | E10: 12 | F10: 62 | G10: 1017 | H10: =G10/E10 -> 84.75 | I10: 16.4 | J10: 9 | K10: 0 | L10: 0 | M10: 0 | N10: 0 | O10: 0 | P10: =(F10*0.5+G10/10+J10*6+L10/10+N10*6-O10*2)/E10 -> 15.558333 | Q10: 23 | R10: 38 | S10: 33 | U10: 22.5 | V10: 76 | W10: 20
A11: Chris Bell | B11: Louisville | E11: 11 | F11: 72 | G11: 917 | H11: =G11/E11 -> 83.363636 | I11: 12.7 | J11: 6 | K11: 0 | L11: 0 | M11: 0 | N11: 0 | O11: 0 | P11: =(F11*0.5+G11/10+J11*6+L11/10+N11*6-O11*2)/E11 -> 14.881818 | Q11: 32 | R11: 39 | S11: 38 | U11: 23.2 | V11: 74 | W11: 22.6
A12: Ja'Kobi Lane | B12: USC | E12: 12 | F12: 43 | G12: 525 | H12: =G12/E12 -> 43.75 | I12: 12.2 | J12: 12 | K12: 0 | L12: 0 | M12: 0 | N12: 0 | O12: 0 | P12: =(F12*0.5+G12/10+J12*6+L12/10+N12*6-O12*2)/E12 -> 12.166667 | Q12: 14 | R12: 45 | S12: 29 | U12: 21.7 | V12: 76 | W12: 20.1
A13: Malachi Fields | B13: Notre Dame | E13: 12 | F13: 36 | G13: 630 | H13: =G13/E13 -> 52.5 | I13: 17.5 | J13: 5 | K13: 0 | L13: 0 | M13: 0 | N13: 0 | O13: 1 | P13: =(F13*0.5+G13/10+J13*6+L13/10+N13*6-O13*2)/E13 -> 9.0833333 | Q13: 17 | R13: 20 | S13: 20 | U13: 23.8 | V13: 77 | W13: 20.2
... A16: Skyler Bell | B16: Connecticut | E16: 13 | F16: 101 | G16: 1276 | H16: =G16/E16 -> 98.153846 | I16: 12.6 | J16: 13 | K16: 2 | L16: -2 | M16: -1 | N16: 0 | O16: 1 | P16: =(F16*0.5+G16/10+J16*6+L16/10+N16*6-O16*2)/E16 -> 19.530769 | Q16: 33 | R16: 43 | S16: 38 | U16: 23.8 | V16: 72 | W16: 20.2
A17: Bryce Lance | B17: North Dakota State | E17: 1 | F17: 3 | G17: 32 | H17: =G17/E17 -> 32 | I17: 10.7 | J17: 0 | K17: 1 | L17: 8 | M17: 8 | N17: 0 | O17: 0 | P17: =(F17*0.5+G17/10+J17*6+L17/10+N17*6-O17*2)/E17 -> 5.5 | Q17: 15 | R17: 0 | S17: 5 | U17: 23.6 | V17: 75 | W17: N/A
A18: Ted Hurst | B18: Georgia State | E18: 12 | F18: 56 | G18: 961 | H18: =G18/E18 -> 80.083333 | I18: 17.2 | J18: 9 | K18: 0 | L18: 0 | M18: 0 | N18: 0 | O18: 0 | P18: =(F18*0.5+G18/10+J18*6+L18/10+N18*6-O18*2)/E18 -> 14.841667 | Q18: 21 | R18: 43 | S18: 37 | U18: 21.8 | V18: 76 | W18: 20.2
A19: Deion Burks | B19: Oklahoma | E19: 13 | F19: 57 | G19: 620 | H19: =G19/E19 -> 47.692308 | I19: 10.9 | J19: 4 | K19: 6 | L19: -3 | M19: -0.5 | N19: 0 | O19: 0 | P19: =(F19*0.5+G19/10+J19*6+L19/10+N19*6-O19*2)/E19 -> 8.7846154 | Q19: 22 | R19: 24 | S19: 21 | U19: 23.3 | V19: 70 | W19: 20.7
A20: Brenen Thompson | B20: Mississippi State | E20: 13 | F20: 57 | G20: 1054 | H20: =G20/E20 -> 81.076923 | I20: 18.5 | J20: 6 | K20: 4 | L20: 14 | M20: 3.5 | N20: 1 | O20: 0 | P20: =(F20*0.5+G20/10+J20*6+L20/10+N20*6-O20*2)/E20 -> 13.638462 | Q20: 23 | R20: 30 | S20: 31 | U20: 22.7 | V20: 69 | W20: 22.1
A21: Jeff Caldwell | B21: Cincinnati | E21: 12 | F21: 32 | G21: 478 | H21: =G21/E21 -> 39.833333 | I21: 14.9 | J21: 6 | K21: 0 | L21: 0 | M21: 0 | N21: 0 | O21: 0 | P21: =(F21*0.5+G21/10+J21*6+L21/10+N21*6-O21*2)/E21 -> 8.3166667 | Q21: 15 | R21: 22 | S21: 19 | U21: 25.1 | V21: 77 | W21: N/A
A22: CJ Daniels | B22: Miami | E22: 12 | F22: 50 | G22: 557 | H22: =G22/E22 -> 46.416667 | I22: 11.1 | J22: 7 | K22: 0 | L22: 0 | M22: 0 | N22: 0 | O22: 0 | P22: =(F22*0.5+G22/10+J22*6+L22/10+N22*6-O22*2)/E22 -> 10.225 | Q22: 19 | R22: 29 | S22: 23 | U22: 24.3 | V22: 74 | W22: 19.7
A23: Caullin Lacy | B23: Louisville | E23: 12 | F23: 91 | G23: 1316 | H23: =G23/E23 -> 109.66667 | I23: 14.5 | J23: 7 | K23: 0 | L23: 0 | M23: 0 | N23: 0 | O23: 0 | P23: =(F23*0.5+G23/10+J23*6+L23/10+N23*6-O23*2)/E23 -> 18.258333 | Q23: 34 | R23: 27 | S23: 33 | U23: 24.3 | V23: 69 | W23: 20.7
A24: Donaven McCulley | B24: Michigan | E24: 12 | F24: 48 | G24: 644 | H24: =G24/E24 -> 53.666667 | I24: 13.4 | J24: 6 | K24: 3 | L24: -1 | M24: -0.3 | N24: 0 | O24: 0 | P24: =(F24*0.5+G24/10+J24*6+L24/10+N24*6-O24*2)/E24 -> 10.358333 | Q24: 22 | R24: 33 | S24: 29 | U24: 23.2 | V24: 77 | W24: 20.6
A25: Chris Hilton Jr. | B25: LSU | E25: 4 | F25: 9 | G25: 243 | H25: =G25/E25 -> 60.75 | I25: 27 | J25: 3 | K25: 0 | L25: 0 | M25: 0 | N25: 0 | O25: 0 | P25: =(F25*0.5+G25/10+J25*6+L25/10+N25*6-O25*2)/E25 -> 11.7 | Q25: 9 | R25: 34 | S25: 26 | U25: 23.5 | V25: 72 | W25: 21.9
A26: J. Michael Sturdivant | B26: Florida | E26: 12 | F26: 65 | G26: 755 | H26: =G26/E26 -> 62.916667 | I26: 11.6 | J26: 7 | K26: 2 | L26: -8 | M26: -4 | N26: 0 | O26: 0 | P26: =(F26*0.5+G26/10+J26*6+L26/10+N26*6-O26*2)/E26 -> 12.433333 | Q26: 22 | R26: 30 | S26: 26 | U26: 23.6 | V26: 75 | W26: 20
A27: De'Zhaun Stribling | B27: Ole Miss | E27: 11 | F27: 52 | G27: 892 | H27: =G27/E27 -> 81.090909 | I27: 17.2 | J27: 6 | K27: 0 | L27: 0 | M27: 0 | N27: 0 | O27: 0 | P27: =(F27*0.5+G27/10+J27*6+L27/10+N27*6-O27*2)/E27 -> 13.745455 | Q27: 21 | R27: 30 | S27: 30 | U27: 23.3 | V27: 74 | W27: 19.7
A28: Harrison Wallace III | B28: Ole Miss | E28: 15 | F28: 61 | G28: 934 | H28: =G28/E28 -> 62.266667 | I28: 15.3 | J28: 4 | K28: 3 | L28: 1 | M28: 0.3 | N28: 0 | O28: 1 | P28: =(F28*0.5+G28/10+J28*6+L28/10+N28*6-O28*2)/E28 -> 9.7333333 | Q28: 18 | R28: 15 | S28: 17 | U28: 23 | V28: 72 | W28: N/A
A29: Jalen Walthall | B29: Hawaii | E29: 10 | F29: 27 | G29: 333 | H29: =G29/E29 -> 33.3 | I29: 12.3 | J29: 1 | K29: 0 | L29: 0 | M29: 0 | N29: 0 | O29: 0 | P29: =(F29*0.5+G29/10+J29*6+L29/10+N29*6-O29*2)/E29 -> 5.28 | Q29: 13 | R29: 10 | S29: 13 | U29: 23.5 | V29: 73 | W29: N/A
A30: Eric Rivers | B30: Georgia Tech | E30: 12 | F30: 62 | G30: 1172 | H30: =G30/E30 -> 97.666667 | I30: 18.9 | J30: 12 | K30: 1 | L30: -3 | M30: -3 | N30: 0 | O30: 1 | P30: =(F30*0.5+G30/10+J30*6+L30/10+N30*6-O30*2)/E30 -> 18.158333 | Q30: 30 | R30: 50 | S30: 46 | U30: 23.6 | V30: 70 | W30: 22
A31: Josh Cameron | B31: Baylor | E31: 12 | F31: 69 | G31: 872 | H31: =G31/E31 -> 72.666667 | I31: 12.6 | J31: 9 | K31: 0 | L31: 0 | M31: 0 | N31: 0 | O31: 4 | P31: =(F31*0.5+G31/10+J31*6+L31/10+N31*6-O31*2)/E31 -> 13.975 | Q31: 22 | R31: 29 | S31: 26 | U31: 23.1 | V31: 74 | W31: 21.5
A32: Eric McAlister | B32: TCU | E32: 12 | F32: 72 | G32: 1190 | H32: =G32/E32 -> 99.166667 | I32: 16.5 | J32: 10 | K32: 0 | L32: 0 | M32: 0 | N32: 0 | O32: 3 | P32: =(F32*0.5+G32/10+J32*6+L32/10+N32*6-O32*2)/E32 -> 17.416667 | Q32: 25 | R32: 36 | S32: 35 | U32: 23.4 | V32: 76 | W32: 19.8
A33: Chase Roberts | B33: BYU | E33: 13 | F33: 54 | G33: 802 | H33: =G33/E33 -> 61.692308 | I33: 14.9 | J33: 6 | K33: 0 | L33: 0 | M33: 0 | N33: 0 | O33: 0 | P33: =(F33*0.5+G33/10+J33*6+L33/10+N33*6-O33*2)/E33 -> 11.015385 | Q33: 23 | R33: 43 | S33: 35 | U33: 26.2 | V33: 75 | W33: 23.6
A34: Jordan Hudson | B34: SMU | E34: 11 | F34: 61 | G34: 766 | H34: =G34/E34 -> 69.636364 | I34: 12.6 | J34: 6 | K34: 1 | L34: 6 | M34: 6 | N34: 0 | O34: 1 | P34: =(F34*0.5+G34/10+J34*6+L34/10+N34*6-O34*2)/E34 -> 12.881818 | Q34: 24 | R34: 27 | S34: 25 | U34: 22.4 | V34: 73 | W34: 21.8
A35: Kaden Wetjen | B35: Iowa | E35: 13 | F35: 20 | G35: 151 | H35: =G35/E35 -> 11.615385 | I35: 7.6 | J35: 1 | K35: 15 | L35: 79 | M35: 5.3 | N35: 2 | O35: 1 | P35: =(F35*0.5+G35/10+J35*6+L35/10+N35*6-O35*2)/E35 -> 3.7692308 | Q35: 11 | R35: 8 | S35: 8 | U35: 24.1 | V35: 69 | W35: N/A
A36: Aaron Anderson | B36: LSU | E36: 13 | F36: 61 | G36: 875 | H36: =G36/E36 -> 67.307692 | I36: 14.3 | J36: 5 | K36: 0 | L36: 0 | M36: 0 | N36: 0 | O36: 1 | P36: =(F36*0.5+G36/10+J36*6+L36/10+N36*6-O36*2)/E36 -> 11.230769 | Q36: 18 | R36: 17 | S36: 19 | U36: 23.4 | V36: 68 | W36: N/A
A37: Kendrick Law | B37: Kentucky | E37: 12 | F37: 53 | G37: 540 | H37: =G37/E37 -> 45 | I37: 10.2 | J37: 3 | K37: 8 | L37: 53 | M37: 6.6 | N37: 0 | O37: 0 | P37: =(F37*0.5+G37/10+J37*6+L37/10+N37*6-O37*2)/E37 -> 8.65 | Q37: 23 | R37: 20 | S37: 21 | U37: 22.8 | V37: 71 | W37: 22.2
A38: Reggie Virgil | B38: Texas Tech | E38: 13 | F38: 41 | G38: 816 | H38: =G38/E38 -> 62.769231 | I38: 19.9 | J38: 9 | K38: 0 | L38: 0 | M38: 0 | N38: 0 | O38: 0 | P38: =(F38*0.5+G38/10+J38*6+L38/10+N38*6-O38*2)/E38 -> 12.007692 | Q38: 20 | R38: 42 | S38: 35 | U38: 21.9 | V38: 75 | W38: 20.3
A39: Caleb Douglas | B39: Texas Tech | E39: 13 | F39: 55 | G39: 845 | H39: =G39/E39 -> 65 | I39: 15.4 | J39: 7 | K39: 0 | L39: 0 | M39: 0 | N39: 0 | O39: 0 | P39: =(F39*0.5+G39/10+J39*6+L39/10+N39*6-O39*2)/E39 -> 11.846154 | Q39: 19 | R39: 23 | S39: 23 | U39: 22.6 | V39: 76 | W39: 19
A40: Barion Brown | B40: LSU | E40: 13 | F40: 43 | G40: 539 | H40: =G40/E40 -> 41.461538 | I40: 12.5 | J40: 4 | K40: 12 | L40: 147 | M40: 12.2 | N40: 1 | O40: 0 | P40: =(F40*0.5+G40/10+J40*6+L40/10+N40*6-O40*2)/E40 -> 9.2384615 | Q40: 20 | R40: 16 | S40: 17 | U40: 22.3 | V40: 71 | W40: 18.7
A41: Dillon Bell | B41: Georgia | E41: 12 | F41: 43 | G41: 466 | H41: =G41/E41 -> 38.833333 | I41: 10.8 | J41: 4 | K41: 9 | L41: 107 | M41: 11.9 | N41: 1 | O41: 0 | P41: =(F41*0.5+G41/10+J41*6+L41/10+N41*6-O41*2)/E41 -> 9.0666667 | Q41: 15 | R41: 16 | S41: 14 | U41: 22.4 | V41: 73 | W41: N/A
A42: Emmanuel Henderson Jr. | B42: Kansas | E42: 12 | F42: 45 | G42: 766 | H42: =G42/E42 -> 63.833333 | I42: 17 | J42: 5 | K42: 4 | L42: 16 | M42: 4 | N42: 0 | O42: 0 | P42: =(F42*0.5+G42/10+J42*6+L42/10+N42*6-O42*2)/E42 -> 10.891667 | Q42: 21 | R42: 22 | S42: 25 | U42: 23.1 | V42: 73 | W42: 22.5
...

Sheet Sheet4
A1: Jordyn Tyson Arizona State | B1: =IFERROR(__xludf.DUMMYFUNCTION("SPLIT(A1,CHAR(10))"),"Jordyn Tyson") -> Jordyn Tyson | C1: =IFERROR(__xludf.DUMMYFUNCTION("""COMPUTED_VALUE"""),"Arizona State") -> Arizona State | D1: 6' 2" | E1: 203 lbs | F1: 18.1
A2: Carnell Tate Ohio State | B2: =IFERROR(__xludf.DUMMYFUNCTION("SPLIT(A2,CHAR(10))"),"Carnell Tate") -> Carnell Tate | C2: =IFERROR(__xludf.DUMMYFUNCTION("""COMPUTED_VALUE"""),"Ohio State") -> Ohio State | D2: 6' 2" | E2: 192 lbs | F2: 20.6
A3: Makai Lemon USC | B3: =IFERROR(__xludf.DUMMYFUNCTION("SPLIT(A3,CHAR(10))"),"Makai Lemon") -> Makai Lemon | C3: =IFERROR(__xludf.DUMMYFUNCTION("""COMPUTED_VALUE"""),"USC") -> USC | D3: 5' 11" | E3: 192 lbs | F3: 21.3
A4: KC Concepcion Texas A&M | B4: =IFERROR(__xludf.DUMMYFUNCTION("SPLIT(A4,CHAR(10))"),"KC Concepcion") -> KC Concepcion | C4: =IFERROR(__xludf.DUMMYFUNCTION("""COMPUTED_VALUE"""),"Texas A&M") -> Texas A&M | D4: 6' 0" | E4: 196 lbs | F4: 18.8
A5: Denzel Boston Washington | B5: =IFERROR(__xludf.DUMMYFUNCTION("SPLIT(A5,CHAR(10))"),"Denzel Boston") -> Denzel Boston | C5: =IFERROR(__xludf.DUMMYFUNCTION("""COMPUTED_VALUE"""),"Washington") -> Washington | D5: 6' 4" | E5: 212 lbs | F5: 20.8
A6: Omar Cooper Jr. Indiana | B6: =IFERROR(__xludf.DUMMYFUNCTION("SPLIT(A6,CHAR(10))"),"Omar Cooper Jr.") -> Omar Cooper Jr. | C6: =IFERROR(__xludf.DUMMYFUNCTION("""COMPUTED_VALUE"""),"Indiana") -> Indiana | D6: 6' 0" | E6: 199 lbs | F6: 20.7
A7: Elijah Sarratt Indiana | B7: =IFERROR(__xludf.DUMMYFUNCTION("SPLIT(A7,CHAR(10))"),"Elijah Sarratt") -> Elijah Sarratt | C7: =IFERROR(__xludf.DUMMYFUNCTION("""COMPUTED_VALUE"""),"Indiana") -> Indiana | D7: 6' 3" | E7: 210 lbs | F7: 20.3
A8: Germie Bernard Alabama | B8: =IFERROR(__xludf.DUMMYFUNCTION("SPLIT(A8,CHAR(10))"),"Germie Bernard") -> Germie Bernard | C8: =IFERROR(__xludf.DUMMYFUNCTION("""COMPUTED_VALUE"""),"Alabama") -> Alabama | D8: 6' 1" | E8: 206 lbs | F8: 21.8
A9: Chris Brazzell II Tennessee | B9: =IFERROR(__xludf.DUMMYFUNCTION("SPLIT(A9,CHAR(10))"),"Chris Brazzell II") -> Chris Brazzell II | C9: =IFERROR(__xludf.DUMMYFUNCTION("""COMPUTED_VALUE"""),"Tennessee") -> Tennessee | D9: 6' 4" | E9: 198 lbs | F9: 20
A10: Chris Bell Louisville | B10: =IFERROR(__xludf.DUMMYFUNCTION("SPLIT(A10,CHAR(10))"),"Chris Bell") -> Chris Bell | C10: =IFERROR(__xludf.DUMMYFUNCTION("""COMPUTED_VALUE"""),"Louisville") -> Louisville | D10: 6' 2" | E10: 222 lbs | F10: 22.6
A11: Ja'Kobi Lane USC | B11: =IFERROR(__xludf.DUMMYFUNCTION("SPLIT(A11,CHAR(10))"),"Ja'Kobi Lane") -> Ja'Kobi Lane | C11: =IFERROR(__xludf.DUMMYFUNCTION("""COMPUTED_VALUE"""),"USC") -> USC | D11: 6' 4" | E11: 200 lbs | F11: 20.1
A12: Malachi Fields Notre Dame | B12: =IFERROR(__xludf.DUMMYFUNCTION("SPLIT(A12,CHAR(10))"),"Malachi Fields") -> Malachi Fields | C12: =IFERROR(__xludf.DUMMYFUNCTION("""COMPUTED_VALUE"""),"Notre Dame") -> Notre Dame | D12: 6' 5" | E12: 218 lbs | F12: 20.2
A13: Zachariah Branch Georgia | B13: =IFERROR(__xludf.DUMMYFUNCTION("SPLIT(A13,CHAR(10))"),"Zachariah Branch") -> Zachariah Branch | C13: =IFERROR(__xludf.DUMMYFUNCTION("""COMPUTED_VALUE"""),"Georgia") -> Georgia | D13: 5' 9" | E13: 177 lbs | F13: 21.4
A14: Antonio Williams Clemson | B14: =IFERROR(__xludf.DUMMYFUNCTION("SPLIT(A14,CHAR(10))"),"Antonio Williams") -> Antonio Williams | C14: =IFERROR(__xludf.DUMMYFUNCTION("""COMPUTED_VALUE"""),"Clemson") -> Clemson | D14: 6' 0" | E14: 187 lbs | F14: 19.1
A15: Skyler Bell Connecticut | B15: =IFERROR(__xludf.DUMMYFUNCTION("SPLIT(A15,CHAR(10))"),"Skyler Bell") -> Skyler Bell | C15: =IFERROR(__xludf.DUMMYFUNCTION("""COMPUTED_VALUE"""),"Connecticut") -> Connecticut | D15: 6' 0" | E15: 192 lbs | F15: 20.2
A16: Bryce Lance North Dakota State | B16: =IFERROR(__xludf.DUMMYFUNCTION("SPLIT(A16,CHAR(10))"),"Bryce Lance") -> Bryce Lance | C16: =IFERROR(__xludf.DUMMYFUNCTION("""COMPUTED_VALUE"""),"North Dakota State") -> North Dakota State | D16: 6' 3" | E16: 204 lbs | F16: No Breakout
A17: Ted Hurst Georgia State | B17: =IFERROR(__xludf.DUMMYFUNCTION("SPLIT(A17,CHAR(10))"),"Ted Hurst") -> Ted Hurst | C17: =IFERROR(__xludf.DUMMYFUNCTION("""COMPUTED_VALUE"""),"Georgia State") -> Georgia State | D17: 6' 4" | E17: 206 lbs | F17: 20.2
A18: Deion Burks Oklahoma | B18: =IFERROR(__xludf.DUMMYFUNCTION("SPLIT(A18,CHAR(10))"),"Deion Burks") -> Deion Burks | C18: =IFERROR(__xludf.DUMMYFUNCTION("""COMPUTED_VALUE"""),"Oklahoma") -> Oklahoma | D18: 5' 10" | E18: 180 lbs | F18: 20.7
A19: Brenen Thompson Mississippi State | B19: =IFERROR(__xludf.DUMMYFUNCTION("SPLIT(A19,CHAR(10))"),"Brenen Thompson") -> Brenen Thompson | C19: =IFERROR(__xludf.DUMMYFUNCTION("""COMPUTED_VALUE"""),"Mississippi State") -> Mississippi State | D19: 5' 9" | E19: 164 lbs | F19: 22.1
A20: De'Zhaun Stribling Ole Miss | B20: =IFERROR(__xludf.DUMMYFUNCTION("SPLIT(A20,CHAR(10))"),"De'Zhaun Stribling") -> De'Zhaun Stribling | C20: =IFERROR(__xludf.DUMMYFUNCTION("""COMPUTED_VALUE"""),"Ole Miss") -> Ole Miss | D20: 6' 2" | E20: 207 lbs | F20: 19.7
A21: Caleb Douglas Texas Tech | B21: =IFERROR(__xludf.DUMMYFUNCTION("SPLIT(A21,CHAR(10))"),"Caleb Douglas") -> Caleb Douglas | C21: =IFERROR(__xludf.DUMMYFUNCTION("""COMPUTED_VALUE"""),"Texas Tech") -> Texas Tech | D21: 6' 4" | E21: 206 lbs | F21: 19
A22: Zavion Thomas LSU | B22: =IFERROR(__xludf.DUMMYFUNCTION("SPLIT(A22,CHAR(10))"),"Zavion Thomas") -> Zavion Thomas | C22: =IFERROR(__xludf.DUMMYFUNCTION("""COMPUTED_VALUE"""),"LSU") -> LSU | D22: 5' 10" | E22: 190 lbs | F22: No Breakout
